Workbook

Sheet 汇总
A2: 未决久期 | B2: 再保前 | C2: 再保后 | F2: 未到期久期 | G2: 再保前 | H2: 再保后
A3: 非融资性保证险 | B3: =B4 -> 0 | C3: =B3 -> 0 | F3: =A3 -> 非融资性保证险 | G3: =G4 -> 0 | H3: =H4 -> 0
A4: 融资性保证险 | B4: =INDIRECT(A4&"!C295") -> 0 | C4: =INDIRECT(A4&"!AS295") -> 0 | F4: =A4 -> 融资性保证险 | G4: =INDIRECT(A4&"!C299") -> 0 | H4: =INDIRECT(A4&"!AS299") -> 0
A5: 财产险 | B5: =INDIRECT(A5&"!C310") -> 0.51726694 | C5: =INDIRECT(A5&"!AY310") -> 0.45177905 | F5: =A5 -> 财产险 | G5: =INDIRECT(A5&"!C314") -> 0.65016097 | H5: =INDIRECT(A5&"!AY314") -> 0.59379024
A6: 车其他 | B6: =INDIRECT(A6&"!C310") -> 0.24054746 | C6: =B6 -> 0.24054746 | F6: =A6 -> 车其他 | G6: =INDIRECT(A6&"!C314") -> 0.43669713 | H6: =G6 -> 0.43669713
A7: 车损 | B7: =INDIRECT(A7&"!C310") -> 0.26627695 | C7: =B7 -> 0.26627695 | F7: =A7 -> 车损 | G7: =INDIRECT(A7&"!C314") -> 0.46012257 | H7: =G7 -> 0.46012257
A8: 健康险 | B8: =INDIRECT(A8&"!C310") -> 0.41731565 | C8: =B8 -> 0.41731565 | F8: =A8 -> 健康险 | G8: =INDIRECT(A8&"!C314") -> 0.57033078 | H8: =健康险!AY314 -> 0.55949977
A9: 交强险 | B9: =INDIRECT(A9&"!C310") -> 0.4096303 | C9: =B9 -> 0.4096303 | F9: =A9 -> 交强险 | G9: =INDIRECT(A9&"!C314") -> 0.55063179 | H9: =G9 -> 0.55063179
A10: 奶牛 | B10: =INDIRECT(A10&"!C310") -> 0.30683273 | C10: =INDIRECT(A10&"!AY310") -> 0.32641064 | F10: =A10 -> 奶牛 | G10: =INDIRECT(A10&"!C314") -> 0.4972425 | H10: =INDIRECT(A10&"!AY314") -> 0.51723809
A11: 能繁母猪 | B11: =INDIRECT(A11&"!C310") -> 0.32013728 | C11: =INDIRECT(A11&"!AY310") -> 0.35464635 | F11: =A11 -> 能繁母猪 | G11: =INDIRECT(A11&"!C314") -> 0.49046375 | H11: =INDIRECT(A11&"!AY314") -> 0.51913819
A12: 秋粮 | B12: =INDIRECT(A12&"!C310") -> 0.72254961 | C12: =INDIRECT(A12&"!AY310") -> 0.60692373 | F12: =A12 -> 秋粮 | G12: =INDIRECT(A12&"!C314") -> 0.85886178 | H12: =INDIRECT(A12&"!AY314") -> 0.78485679
A13: 商业三者 | B13: =INDIRECT(A13&"!C310") -> 0.55013436 | C13: =B13 -> 0.55013436 | F13: =A13 -> 商业三者 | G13: =INDIRECT(A13&"!C314") -> 0.6467783 | H13: =G13 -> 0.6467783
A14: 夏粮 | B14: =INDIRECT(A14&"!C310") -> 0.31138548 | C14: =夏粮!AU310 -> 0.2211924 | F14: =A14 -> 夏粮 | G14: =INDIRECT(A14&"!C314") -> 0.61032806 | H14: =INDIRECT(A14&"!AU314") -> 0.55678369
A15: 养殖险其他 | B15: =INDIRECT(A15&"!C310") -> 0.17548387 | C15: =INDIRECT(A15&"!AY310") -> 0.2140238 | F15: =A15 -> 养殖险其他 | G15: =INDIRECT(A15&"!C314") -> 0.37560044 | H15: =INDIRECT(A15&"!AY314") -> 0.3754093
A16: 意外险 | B16: =INDIRECT(A16&"!C311") -> 0.91086691 | C16: =意外险!AU311 -> 0.93837529 | F16: =A16 -> 意外险 | G16: =INDIRECT(A16&"!C315") -> 0.69183081 | H16: =意外险!AU315 -> 0.7589173
A17: 育肥猪 | B17: =INDIRECT(A17&"!C310") -> 0.3273343 | C17: =育肥猪!AU310 -> 0.35797608 | F17: =A17 -> 育肥猪 | G17: =INDIRECT(A17&"!C314") -> 0.573994 | H17: =育肥猪!AU314 -> 0.57030623
A18: 种植险特色 | B18: =INDIRECT(A18&"!C310") -> 0.23675013 | C18: =种植险特色!AY310 -> 0.19820794 | F18: =A18 -> 种植险特色 | G18: =INDIRECT(A18&"!C314") -> 0.39151414 | H18: =INDIRECT(A18&"!AY314") -> 0.38468961
A23: 未决久期 | B23: 再保前 | C23: 再保后 | F23: 未到期久期 | G23: 再保前 | H23: 再保后
A24: 非融资性保证险 | B24: =非融资性保证险!K260 -> 0 | C24: =B24 -> 0 | F24: =A24 -> 非融资性保证险 | G24: =G25 -> 0 | H24: =H25 -> 0
A25: 融资性保证险 | B25: =融资性保证险!K263 -> 0 | C25: =INDIRECT(A25&"!AS295") -> 0 | F25: =A25 -> 融资性保证险 | G25: =INDIRECT(A25&"!C299") -> 0 | H25: =INDIRECT(A25&"!AS299") -> 0
A26: 财产险 | B26: =INDIRECT(A26&"!K263")+[1]财产险008链梯法!$BC$260 -> 68669735 | C26: =INDIRECT(A26&"!BC263") -> 202303 | F26: =A26 -> 财产险 | G26: =INDIRECT(A26&"!C310") -> 0.51726694 | H26: =INDIRECT(A26&"!AU310") -> 0
A27: 车其他 | B27: =INDIRECT(A27&"!K263") -> 143327.93 | C27: =B27 -> 143327.93 | F27: =A27 -> 车其他 | G27: =INDIRECT(A27&"!C310") -> 0.24054746 | H27: =G27 -> 0.24054746
A28: 车损 | B28: =INDIRECT(A28&"!K263")+E28 -> 13401454 | C28: =B28 -> 13401454 | E28: 12917885 | F28: =A28 -> 车损 | G28: =INDIRECT(A28&"!C310") -> 0.26627695 | H28: =INDIRECT(A28&"!AU310") -> 0
A29: 健康险 | B29: =INDIRECT(A29&"!K263") -> 1.3052183e+08 | C29: =INDIRECT(A29&"!BC263") -> 0 | F29: =A29 -> 健康险 | G29: =INDIRECT(A29&"!C310") -> 0.41731565 | H29: =INDIRECT(A29&"!AU310") -> 0
A30: 交强险 | B30: =INDIRECT(A30&"!K263") -> 28661007 | C30: =B30 -> 28661007 | F30: =A30 -> 交强险 | G30: =INDIRECT(A30&"!C310") -> 0.4096303 | H30: =G30 -> 0.4096303
A31: 奶牛 | B31: =INDIRECT(A31&"!K263") -> 2815158.4 | C31: =INDIRECT(A31&"!BC263") -> 0 | F31: =A31 -> 奶牛 | G31: =INDIRECT(A31&"!C310") -> 0.30683273 | H31: =INDIRECT(A31&"!AU310") -> 0
A32: 能繁母猪 | B32: =INDIRECT(A32&"!K263") -> 6014507.8 | C32: =INDIRECT(A32&"!BC263") -> 0 | F32: =A32 -> 能繁母猪 | G32: =INDIRECT(A32&"!C310") -> 0.32013728 | H32: =INDIRECT(A32&"!AU310") -> 0
A33: 秋粮 | B33: =INDIRECT(A33&"!K263") -> 1.1568627e+08 | C33: =INDIRECT(A33&"!BC263") -> 0 | F33: =A33 -> 秋粮 | G33: =INDIRECT(A33&"!C310") -> 0.72254961 | H33: =INDIRECT(A33&"!AU310") -> 0
A34: 商业三者 | B34: =INDIRECT(A34&"!K263") -> 18179920 | C34: =B34 -> 18179920 | F34: =A34 -> 商业三者 | G34: =INDIRECT(A34&"!C310") -> 0.55013436 | H34: =G34 -> 0.55013436
A35: 夏粮 | B35: =INDIRECT(A35&"!K263")+D43 -> 55382883 | C35: =B35-C43 -> 45544123 | F35: =A35 -> 夏粮 | G35: =INDIRECT(A35&"!C310") -> 0.31138548 | H35: =INDIRECT(A35&"!AU310") -> 0.2211924
A36: 养殖险其他 | B36: =INDIRECT(A36&"!K263") -> 2678724.7 | C36: =INDIRECT(A36&"!BC263") -> 0 | F36: =A36 -> 养殖险其他 | G36: =INDIRECT(A36&"!C310") -> 0.17548387 | H36: =INDIRECT(A36&"!AU310") -> 0
A37: 意外险 | B37: =INDIRECT(A37&"!L264") -> 25746977 | C37: =INDIRECT(A37&"!BD264") -> 25280045 | F37: =A37 -> 意外险 | G37: =INDIRECT(A37&"!C311") -> 0.91086691 | H37: =INDIRECT(A37&"!AU311") -> 0.93837529
A38: 育肥猪 | B38: =INDIRECT(A38&"!K263") -> 37235393 | C38: =INDIRECT(A38&"!BC263") -> 29935624 | F38: =A38 -> 育肥猪 | G38: =INDIRECT(A38&"!C310") -> 0.3273343 | H38: =INDIRECT(A38&"!AU310") -> 0.35797608
A39: 种植险特色 | B39: =INDIRECT(A39&"!K263") -> 33991009 | C39: =INDIRECT(A39&"!BC263") -> 0 | F39: =A39 -> 种植险特色 | G39: =INDIRECT(A39&"!C310") -> 0.23675013 | H39: =INDIRECT(A39&"!AU310") -> 0
C43: 9838759.8 | D43: -1783470.2

Sheet 非融资性保证险
B2: 黄色底格要求可自行填写或输入公式 | AT2: 黄色底格要求可自行填写或输入公式
B3: 再保前 | AT3: 再保后
B4: 累计已决三角形 | AJ4: 单位：人民币元 | AT4: 累计已决三角形 | CB4: 单位：人民币元
B5: 事故月份 | C5: 进展区间 | AT5: 事故月份 | AU5: 进展区间
C6: 1 | D6: 2 | E6: 3 | F6: 4 | G6: 5 | H6: 6 | I6: 7 | J6: 8 | K6: 9 | L6: 10 | M6: 11 | N6: 12 | O6: 13 | P6: 14 | Q6: 15 | R6: 16 | S6: 17 | T6: 18 | U6: 19 | V6: 20 | W6: 21 | X6: 22 | Y6: 23 | Z6: 24 | AA6: 25 | AB6: 26 | AC6: 27 | AD6: 28 | AE6: 29 | AF6: 30 | AG6: 31 | AH6: 32 | AI6: 33 | AJ6: 34 | AK6: 35 | AU6: 1 | AV6: 2 | AW6: 3 | AX6: 4 | AY6: 5 | AZ6: 6 | BA6: 7 | BB6: 8 | BC6: 9 | BD6: 10 | BE6: 11 | BF6: 12 | BG6: 13 | BH6: 14 | BI6: 15 | BJ6: 16 | BK6: 17 | BL6: 18 | BM6: 19 | BN6: 20 | BO6: 21 | BP6: 22 | BQ6: 23 | BR6: 24 | BS6: 25 | BT6: 26 | BU6: 27 | BV6: 28 | BW6: 29 | BX6: 30 | BY6: 31 | BZ6: 32 | CA6: 33 | CB6: 34 | CC6: 35
B7: 201506 | C7: 0 | D7: 0 | E7: 0 | F7: 0 | G7: 0 | H7: 0 | I7: 0 | J7: 0 | K7: 0 | L7: 0 | M7: 0 | N7: 0 | O7: 0 | P7: 0 | Q7: 0 | R7: 0 | S7: 0 | T7: 0 | U7: 0 | V7: 0 | W7: 0 | X7: 0 | Y7: 0 | Z7: 0 | AA7: 0 | AB7: 0 | AC7: 0 | AD7: 0 | AE7: 0 | AF7: 0 | AG7: 0 | AH7: 0 | AI7: 0 | AJ7: 0 | AK7: 0 | AT7: 201506 | AU7: 0 | AV7: 0 | AW7: 0 | AX7: 0 | AY7: 0 | AZ7: 0 | BA7: 0 | BB7: 0 | BC7: 0 | BD7: 0 | BE7: 0 | BF7: 0 | BG7: 0 | BH7: 0 | BI7: 0 | BJ7: 0 | BK7: 0 | BL7: 0 | BM7: 0 | BN7: 0 | BO7: 0 | BP7: 0 | BQ7: 0 | BR7: 0 | BS7: 0 | BT7: 0 | BU7: 0 | BV7: 0 | BW7: 0 | BX7: 0 | BY7: 0 | BZ7: 0 | CA7: 0 | CB7: 0 | CC7: 0
B8: 201509 | C8: 0 | D8: 0 | E8: 0 | F8: 0 | G8: 0 | H8: 0 | I8: 0 | J8: 0 | K8: 0 | L8: 0 | M8: 0 | N8: 0 | O8: 0 | P8: 0 | Q8: 0 | R8: 0 | S8: 0 | T8: 0 | U8: 0 | V8: 0 | W8: 0 | X8: 0 | Y8: 0 | Z8: 0 | AA8: 0 | AB8: 0 | AC8: 0 | AD8: 0 | AE8: 0 | AF8: 0 | AG8: 0 | AH8: 0 | AI8: 0 | AJ8: 0 | AT8: 201509 | AU8: 0 | AV8: 0 | AW8: 0 | AX8: 0 | AY8: 0 | AZ8: 0 | BA8: 0 | BB8: 0 | BC8: 0 | BD8: 0 | BE8: 0 | BF8: 0 | BG8: 0 | BH8: 0 | BI8: 0 | BJ8: 0 | BK8: 0 | BL8: 0 | BM8: 0 | BN8: 0 | BO8: 0 | BP8: 0 | BQ8: 0 | BR8: 0 | BS8: 0 | BT8: 0 | BU8: 0 | BV8: 0 | BW8: 0 | BX8: 0 | BY8: 0 | BZ8: 0 | CA8: 0 | CB8: 0
B9: 201512 | C9: 0 | D9: 0 | E9: 0 | F9: 0 | G9: 0 | H9: 0 | I9: 0 | J9: 0 | K9: 0 | L9: 0 | M9: 0 | N9: 0 | O9: 0 | P9: 0 | Q9: 0 | R9: 0 | S9: 0 | T9: 0 | U9: 0 | V9: 0 | W9: 0 | X9: 0 | Y9: 0 | Z9: 0 | AA9: 0 | AB9: 0 | AC9: 0 | AD9: 0 | AE9: 0 | AF9: 0 | AG9: 0 | AH9: 0 | AI9: 0 | AT9: 201512 | AU9: 0 | AV9: 0 | AW9: 0 | AX9: 0 | AY9: 0 | AZ9: 0 | BA9: 0 | BB9: 0 | BC9: 0 | BD9: 0 | BE9: 0 | BF9: 0 | BG9: 0 | BH9: 0 | BI9: 0 | BJ9: 0 | BK9: 0 | BL9: 0 | BM9: 0 | BN9: 0 | BO9: 0 | BP9: 0 | BQ9: 0 | BR9: 0 | BS9: 0 | BT9: 0 | BU9: 0 | BV9: 0 | BW9: 0 | BX9: 0 | BY9: 0 | BZ9: 0 | CA9: 0
B10: 201603 | C10: 0 | D10: 0 | E10: 0 | F10: 0 | G10: 0 | H10: 0 | I10: 0 | J10: 0 | K10: 0 | L10: 0 | M10: 0 | N10: 0 | O10: 0 | P10: 0 | Q10: 0 | R10: 0 | S10: 0 | T10: 0 | U10: 0 | V10: 0 | W10: 0 | X10: 0 | Y10: 0 | Z10: 0 | AA10: 0 | AB10: 0 | AC10: 0 | AD10: 0 | AE10: 0 | AF10: 0 | AG10: 0 | AH10: 0 | AT10: 201603 | AU10: 0 | AV10: 0 | AW10: 0 | AX10: 0 | AY10: 0 | AZ10: 0 | BA10: 0 | BB10: 0 | BC10: 0 | BD10: 0 | BE10: 0 | BF10: 0 | BG10: 0 | BH10: 0 | BI10: 0 | BJ10: 0 | BK10: 0 | BL10: 0 | BM10: 0 | BN10: 0 | BO10: 0 | BP10: 0 | BQ10: 0 | BR10: 0 | BS10: 0 | BT10: 0 | BU10: 0 | BV10: 0 | BW10: 0 | BX10: 0 | BY10: 0 | BZ10: 0
B11: 201606 | C11: 0 | D11: 0 | E11: 0 | F11: 0 | G11: 0 | H11: 0 | I11: 0 | J11: 0 | K11: 0 | L11: 0 | M11: 0 | N11: 0 | O11: 0 | P11: 0 | Q11: 0 | R11: 0 | S11: 0 | T11: 0 | U11: 0 | V11: 0 | W11: 0 | X11: 0 | Y11: 0 | Z11: 0 | AA11: 0 | AB11: 0 | AC11: 0 | AD11: 0 | AE11: 0 | AF11: 0 | AG11: 0 | AT11: 201606 | AU11: 0 | AV11: 0 | AW11: 0 | AX11: 0 | AY11: 0 | AZ11: 0 | BA11: 0 | BB11: 0 | BC11: 0 | BD11: 0 | BE11: 0 | BF11: 0 | BG11: 0 | BH11: 0 | BI11: 0 | BJ11: 0 | BK11: 0 | BL11: 0 | BM11: 0 | BN11: 0 | BO11: 0 | BP11: 0 | BQ11: 0 | BR11: 0 | BS11: 0 | BT11: 0 | BU11: 0 | BV11: 0 | BW11: 0 | BX11: 0 | BY11: 0
B12: 201609 | C12: 0 | D12: 0 | E12: 0 | F12: 0 | G12: 0 | H12: 0 | I12: 0 | J12: 0 | K12: 0 | L12: 0 | M12: 0 | N12: 0 | O12: 0 | P12: 0 | Q12: 0 | R12: 0 | S12: 0 | T12: 0 | U12: 0 | V12: 0 | W12: 0 | X12: 0 | Y12: 0 | Z12: 0 | AA12: 0 | AB12: 0 | AC12: 0 | AD12: 0 | AE12: 0 | AF12: 0 | AT12: 201609 | AU12: 0 | AV12: 0 | AW12: 0 | AX12: 0 | AY12: 0 | AZ12: 0 | BA12: 0 | BB12: 0 | BC12: 0 | BD12: 0 | BE12: 0 | BF12: 0 | BG12: 0 | BH12: 0 | BI12: 0 | BJ12: 0 | BK12: 0 | BL12: 0 | BM12: 0 | BN12: 0 | BO12: 0 | BP12: 0 | BQ12: 0 | BR12: 0 | BS12: 0 | BT12: 0 | BU12: 0 | BV12: 0 | BW12: 0 | BX12: 0
B13: 201612 | C13: 0 | D13: 0 | E13: 0 | F13: 0 | G13: 0 | H13: 0 | I13: 0 | J13: 0 | K13: 0 | L13: 0 | M13: 0 | N13: 0 | O13: 0 | P13: 0 | Q13: 0 | R13: 0 | S13: 0 | T13: 0 | U13: 0 | V13: 0 | W13: 0 | X13: 0 | Y13: 0 | Z13: 0 | AA13: 0 | AB13: 0 | AC13: 0 | AD13: 0 | AE13: 0 | AT13: 201612 | AU13: 0 | AV13: 0 | AW13: 0 | AX13: 0 | AY13: 0 | AZ13: 0 | BA13: 0 | BB13: 0 | BC13: 0 | BD13: 0 | BE13: 0 | BF13: 0 | BG13: 0 | BH13: 0 | BI13: 0 | BJ13: 0 | BK13: 0 | BL13: 0 | BM13: 0 | BN13: 0 | BO13: 0 | BP13: 0 | BQ13: 0 | BR13: 0 | BS13: 0 | BT13: 0 | BU13: 0 | BV13: 0 | BW13: 0
B14: 201703 | C14: 0 | D14: 0 | E14: 0 | F14: 0 | G14: 0 | H14: 0 | I14: 0 | J14: 0 | K14: 0 | L14: 0 | M14: 0 | N14: 0 | O14: 0 | P14: 0 | Q14: 0 | R14: 0 | S14: 0 | T14: 0 | U14: 0 | V14: 0 | W14: 0 | X14: 0 | Y14: 0 | Z14: 0 | AA14: 0 | AB14: 0 | AC14: 0 | AD14: 0 | AT14: 201703 | AU14: 0 | AV14: 0 | AW14: 0 | AX14: 0 | AY14: 0 | AZ14: 0 | BA14: 0 | BB14: 0 | BC14: 0 | BD14: 0 | BE14: 0 | BF14: 0 | BG14: 0 | BH14: 0 | BI14: 0 | BJ14: 0 | BK14: 0 | BL14: 0 | BM14: 0 | BN14: 0 | BO14: 0 | BP14: 0 | BQ14: 0 | BR14: 0 | BS14: 0 | BT14: 0 | BU14: 0 | BV14: 0
B15: 201706 | C15: 0 | D15: 0 | E15: 0 | F15: 0 | G15: 0 | H15: 0 | I15: 0 | J15: 0 | K15: 0 | L15: 0 | M15: 0 | N15: 0 | O15: 0 | P15: 0 | Q15: 0 | R15: 0 | S15: 0 | T15: 0 | U15: 0 | V15: 0 | W15: 0 | X15: 0 | Y15: 0 | Z15: 0 | AA15: 0 | AB15: 0 | AC15: 0 | AT15: 201706 | AU15: 0 | AV15: 0 | AW15: 0 | AX15: 0 | AY15: 0 | AZ15: 0 | BA15: 0 | BB15: 0 | BC15: 0 | BD15: 0 | BE15: 0 | BF15: 0 | BG15: 0 | BH15: 0 | BI15: 0 | BJ15: 0 | BK15: 0 | BL15: 0 | BM15: 0 | BN15: 0 | BO15: 0 | BP15: 0 | BQ15: 0 | BR15: 0 | BS15: 0 | BT15: 0 | BU15: 0
B16: 201709 | C16: 0 | D16: 0 | E16: 0 | F16: 0 | G16: 0 | H16: 0 | I16: 0 | J16: 0 | K16: 0 | L16: 0 | M16: 0 | N16: 0 | O16: 0 | P16: 0 | Q16: 0 | R16: 0 | S16: 0 | T16: 0 | U16: 0 | V16: 0 | W16: 0 | X16: 0 | Y16: 0 | Z16: 0 | AA16: 0 | AB16: 0 | AT16: 201709 | AU16: 0 | AV16: 0 | AW16: 0 | AX16: 0 | AY16: 0 | AZ16: 0 | BA16: 0 | BB16: 0 | BC16: 0 | BD16: 0 | BE16: 0 | BF16: 0 | BG16: 0 | BH16: 0 | BI16: 0 | BJ16: 0 | BK16: 0 | BL16: 0 | BM16: 0 | BN16: 0 | BO16: 0 | BP16: 0 | BQ16: 0 | BR16: 0 | BS16: 0 | BT16: 0
B17: 201712 | C17: 0 | D17: 0 | E17: 0 | F17: 0 | G17: 0 | H17: 0 | I17: 0 | J17: 0 | K17: 0 | L17: 0 | M17: 0 | N17: 0 | O17: 0 | P17: 0 | Q17: 0 | R17: 0 | S17: 0 | T17: 0 | U17: 0 | V17: 0 | W17: 0 | X17: 0 | Y17: 0 | Z17: 0 | AA17: 0 | AT17: 201712 | AU17: 0 | AV17: 0 | AW17: 0 | AX17: 0 | AY17: 0 | AZ17: 0 | BA17: 0 | BB17: 0 | BC17: 0 | BD17: 0 | BE17: 0 | BF17: 0 | BG17: 0 | BH17: 0 | BI17: 0 | BJ17: 0 | BK17: 0 | BL17: 0 | BM17: 0 | BN17: 0 | BO17: 0 | BP17: 0 | BQ17: 0 | BR17: 0 | BS17: 0
B18: 201803 | C18: 0 | D18: 0 | E18: 0 | F18: 0 | G18: 0 | H18: 0 | I18: 0 | J18: 0 | K18: 0 | L18: 0 | M18: 0 | N18: 0 | O18: 0 | P18: 0 | Q18: 0 | R18: 0 | S18: 0 | T18: 0 | U18: 0 | V18: 0 | W18: 0 | X18: 0 | Y18: 0 | Z18: 0 | AT18: 201803 | AU18: 0 | AV18: 0 | AW18: 0 | AX18: 0 | AY18: 0 | AZ18: 0 | BA18: 0 | BB18: 0 | BC18: 0 | BD18: 0 | BE18: 0 | BF18: 0 | BG18: 0 | BH18: 0 | BI18: 0 | BJ18: 0 | BK18: 0 | BL18: 0 | BM18: 0 | BN18: 0 | BO18: 0 | BP18: 0 | BQ18: 0 | BR18: 0
B19: 201806 | C19: 0 | D19: 0 | E19: 0 | F19: 0 | G19: 0 | H19: 0 | I19: 0 | J19: 0 | K19: 0 | L19: 0 | M19: 0 | N19: 0 | O19: 0 | P19: 0 | Q19: 0 | R19: 0 | S19: 0 | T19: 0 | U19: 0 | V19: 0 | W19: 0 | X19: 0 | Y19: 0 | AT19: 201806 | AU19: 0 | AV19: 0 | AW19: 0 | AX19: 0 | AY19: 0 | AZ19: 0 | BA19: 0 | BB19: 0 | BC19: 0 | BD19: 0 | BE19: 0 | BF19: 0 | BG19: 0 | BH19: 0 | BI19: 0 | BJ19: 0 | BK19: 0 | BL19: 0 | BM19: 0 | BN19: 0 | BO19: 0 | BP19: 0 | BQ19: 0
B20: 201809 | C20: 0 | D20: 0 | E20: 0 | F20: 0 | G20: 0 | H20: 0 | I20: 0 | J20: 0 | K20: 0 | L20: 0 | M20: 0 | N20: 0 | O20: 0 | P20: 0 | Q20: 0 | R20: 0 | S20: 0 | T20: 0 | U20: 0 | V20: 0 | W20: 0 | X20: 0 | AT20: 201809 | AU20: 0 | AV20: 0 | AW20: 0 | AX20: 0 | AY20: 0 | AZ20: 0 | BA20: 0 | BB20: 0 | BC20: 0 | BD20: 0 | BE20: 0 | BF20: 0 | BG20: 0 | BH20: 0 | BI20: 0 | BJ20: 0 | BK20: 0 | BL20: 0 | BM20: 0 | BN20: 0 | BO20: 0 | BP20: 0
B21: 201812 | C21: 0 | D21: 0 | E21: 0 | F21: 0 | G21: 0 | H21: 0 | I21: 0 | J21: 0 | K21: 0 | L21: 0 | M21: 0 | N21: 0 | O21: 0 | P21: 0 | Q21: 0 | R21: 0 | S21: 0 | T21: 0 | U21: 0 | V21: 0 | W21: 0 | AT21: 201812 | AU21: 0 | AV21: 0 | AW21: 0 | AX21: 0 | AY21: 0 | AZ21: 0 | BA21: 0 | BB21: 0 | BC21: 0 | BD21: 0 | BE21: 0 | BF21: 0 | BG21: 0 | BH21: 0 | BI21: 0 | BJ21: 0 | BK21: 0 | BL21: 0 | BM21: 0 | BN21: 0 | BO21: 0
B22: 201903 | C22: 0 | D22: 0 | E22: 0 | F22: 0 | G22: 0 | H22: 0 | I22: 0 | J22: 0 | K22: 0 | L22: 0 | M22: 0 | N22: 0 | O22: 0 | P22: 0 | Q22: 0 | R22: 0 | S22: 0 | T22: 0 | U22: 0 | V22: 0 | AT22: 201903 | AU22: 0 | AV22: 0 | AW22: 0 | AX22: 0 | AY22: 0 | AZ22: 0 | BA22: 0 | BB22: 0 | BC22: 0 | BD22: 0 | BE22: 0 | BF22: 0 | BG22: 0 | BH22: 0 | BI22: 0 | BJ22: 0 | BK22: 0 | BL22: 0 | BM22: 0 | BN22: 0
B23: 201906 | C23: 0 | D23: 0 | E23: 0 | F23: 0 | G23: 0 | H23: 0 | I23: 0 | J23: 0 | K23: 0 | L23: 0 | M23: 0 | N23: 0 | O23: 0 | P23: 0 | Q23: 0 | R23: 0 | S23: 0 | T23: 0 | U23: 0 | AT23: 201906 | AU23: 0 | AV23: 0 | AW23: 0 | AX23: 0 | AY23: 0 | AZ23: 0 | BA23: 0 | BB23: 0 | BC23: 0 | BD23: 0 | BE23: 0 | BF23: 0 | BG23: 0 | BH23: 0 | BI23: 0 | BJ23: 0 | BK23: 0 | BL23: 0 | BM23: 0
B24: 201909 | C24: 0 | D24: 0 | E24: 0 | F24: 0 | G24: 0 | H24: 0 | I24: 0 | J24: 0 | K24: 0 | L24: 0 | M24: 0 | N24: 0 | O24: 0 | P24: 0 | Q24: 0 | R24: 0 | S24: 0 | T24: 0 | AT24: 201909 | AU24: 0 | AV24: 0 | AW24: 0 | AX24: 0 | AY24: 0 | AZ24: 0 | BA24: 0 | BB24: 0 | BC24: 0 | BD24: 0 | BE24: 0 | BF24: 0 | BG24: 0 | BH24: 0 | BI24: 0 | BJ24: 0 | BK24: 0 | BL24: 0
B25: 201912 | C25: 0 | D25: 0 | E25: 0 | F25: 0 | G25: 0 | H25: 0 | I25: 0 | J25: 0 | K25: 0 | L25: 0 | M25: 0 | N25: 0 | O25: 0 | P25: 0 | Q25: 0 | R25: 0 | S25: 0 | AT25: 201912 | AU25: 0 | AV25: 0 | AW25: 0 | AX25: 0 | AY25: 0 | AZ25: 0 | BA25: 0 | BB25: 0 | BC25: 0 | BD25: 0 | BE25: 0 | BF25: 0 | BG25: 0 | BH25: 0 | BI25: 0 | BJ25: 0 | BK25: 0
B26: 202003 | C26: 0 | D26: 0 | E26: 0 | F26: 0 | G26: 0 | H26: 0 | I26: 0 | J26: 0 | K26: 0 | L26: 0 | M26: 0 | N26: 0 | O26: 0 | P26: 0 | Q26: 0 | R26: 0 | AT26: 202003 | AU26: 0 | AV26: 0 | AW26: 0 | AX26: 0 | AY26: 0 | AZ26: 0 | BA26: 0 | BB26: 0 | BC26: 0 | BD26: 0 | BE26: 0 | BF26: 0 | BG26: 0 | BH26: 0 | BI26: 0 | BJ26: 0
B27: 202006 | C27: 0 | D27: 0 | E27: 0 | F27: 0 | G27: 0 | H27: 0 | I27: 0 | J27: 0 | K27: 0 | L27: 0 | M27: 0 | N27: 0 | O27: 0 | P27: 0 | Q27: 0 | AT27: 202006 | AU27: 0 | AV27: 0 | AW27: 0 | AX27: 0 | AY27: 0 | AZ27: 0 | BA27: 0 | BB27: 0 | BC27: 0 | BD27: 0 | BE27: 0 | BF27: 0 | BG27: 0 | BH27: 0 | BI27: 0
B28: 202009 | C28: 0 | D28: 0 | E28: 0 | F28: 0 | G28: 0 | H28: 0 | I28: 0 | J28: 0 | K28: 0 | L28: 0 | M28: 0 | N28: 0 | O28: 0 | P28: 0 | AT28: 202009 | AU28: 0 | AV28: 0 | AW28: 0 | AX28: 0 | AY28: 0 | AZ28: 0 | BA28: 0 | BB28: 0 | BC28: 0 | BD28: 0 | BE28: 0 | BF28: 0 | BG28: 0 | BH28: 0
B29: 202012 | C29: 0 | D29: 0 | E29: 0 | F29: 0 | G29: 0 | H29: 0 | I29: 0 | J29: 0 | K29: 0 | L29: 0 | M29: 0 | N29: 0 | O29: 0 | AT29: 202012 | AU29: 0 | AV29: 0 | AW29: 0 | AX29: 0 | AY29: 0 | AZ29: 0 | BA29: 0 | BB29: 0 | BC29: 0 | BD29: 0 | BE29: 0 | BF29: 0 | BG29: 0
B30: 202103 | C30: 0 | D30: 0 | E30: 0 | F30: 0 | G30: 0 | H30: 0 | I30: 0 | J30: 0 | K30: 0 | L30: 0 | M30: 0 | N30: 0 | AT30: 202103 | AU30: 0 | AV30: 0 | AW30: 0 | AX30: 0 | AY30: 0 | AZ30: 0 | BA30: 0 | BB30: 0 | BC30: 0 | BD30: 0 | BE30: 0 | BF30: 0
B31: 202106 | C31: 0 | D31: 0 | E31: 0 | F31: 0 | G31: 0 | H31: 0 | I31: 0 | J31: 0 | K31: 0 | L31: 0 | M31: 0 | AT31: 202106 | AU31: 0 | AV31: 0 | AW31: 0 | AX31: 0 | AY31: 0 | AZ31: 0 | BA31: 0 | BB31: 0 | BC31: 0 | BD31: 0 | BE31: 0
B32: 202109 | C32: 0 | D32: 0 | E32: 0 | F32: 0 | G32: 0 | H32: 0 | I32: 0 | J32: 0 | K32: 0 | L32: 0 | AT32: 202109 | AU32: 0 | AV32: 0 | AW32: 0 | AX32: 0 | AY32: 0 | AZ32: 0 | BA32: 0 | BB32: 0 | BC32: 0 | BD32: 0
B33: 202112 | C33: 0 | D33: 0 | E33: 0 | F33: 0 | G33: 0 | H33: 0 | I33: 0 | J33: 0 | K33: 0 | AT33: 202112 | AU33: 0 | AV33: 0 | AW33: 0 | AX33: 0 | AY33: 0 | AZ33: 0 | BA33: 0 | BB33: 0 | BC33: 0
B34: 202203 | C34: 0 | D34: 0 | E34: 0 | F34: 0 | G34: 0 | H34: 0 | I34: 0 | J34: 0 | AT34: 202203 | AU34: 0 | AV34: 0 | AW34: 0 | AX34: 0 | AY34: 0 | AZ34: 0 | BA34: 0 | BB34: 0
B35: 202206 | C35: 0 | D35: 0 | E35: 0 | F35: 0 | G35: 0 | H35: 0 | I35: 0 | AT35: 202206 | AU35: 0 | AV35: 0 | AW35: 0 | AX35: 0 | AY35: 0 | AZ35: 0 | BA35: 0
B36: 202209 | C36: 0 | D36: 0 | E36: 0 | F36: 0 | G36: 0 | H36: 0 | AT36: 202209 | AU36: 0 | AV36: 0 | AW36: 0 | AX36: 0 | AY36: 0 | AZ36: 0
B37: 202212 | C37: 0 | D37: 0 | E37: 0 | F37: 0 | G37: 0 | AT37: 202212 | AU37: 0 | AV37: 0 | AW37: 0 | AX37: 0 | AY37: 0
B38: 202303 | C38: 0 | D38: 0 | E38: 0 | F38: 0 | AT38: 202303 | AU38: 0 | AV38: 0 | AW38: 0 | AX38: 0
B39: 202306 | C39: 0 | D39: 0 | E39: 0 | AT39: 202306 | AU39: 0 | AV39: 0 | AW39: 0
B40: 202309 | C40: 0 | D40: 0 | AT40: 202309 | AU40: 0 | AV40: 0
B41: 202312 | C41: 0 | AT41: 202312 | AU41: 0
...

Sheet 融资性保证险
B2: 黄色底格要求可自行填写或输入公式 | AT2: 黄色底格要求可自行填写或输入公式
B3: 再保前 | AT3: 再保后
B4: 累计已决三角形 | AJ4: 单位：人民币元 | AT4: 累计已决三角形 | CB4: 单位：人民币元
B5: 事故月份 | C5: 进展区间 | AT5: 事故月份 | AU5: 进展区间
C6: 1 | D6: 2 | E6: 3 | F6: 4 | G6: 5 | H6: 6 | I6: 7 | J6: 8 | K6: 9 | L6: 10 | M6: 11 | N6: 12 | O6: 13 | P6: 14 | Q6: 15 | R6: 16 | S6: 17 | T6: 18 | U6: 19 | V6: 20 | W6: 21 | X6: 22 | Y6: 23 | Z6: 24 | AA6: 25 | AB6: 26 | AC6: 27 | AD6: 28 | AE6: 29 | AF6: 30 | AG6: 31 | AH6: 32 | AI6: 33 | AJ6: 34 | AK6: 35 | AU6: 1 | AV6: 2 | AW6: 3 | AX6: 4 | AY6: 5 | AZ6: 6 | BA6: 7 | BB6: 8 | BC6: 9 | BD6: 10 | BE6: 11 | BF6: 12 | BG6: 13 | BH6: 14 | BI6: 15 | BJ6: 16 | BK6: 17 | BL6: 18 | BM6: 19 | BN6: 20 | BO6: 21 | BP6: 22 | BQ6: 23 | BR6: 24 | BS6: 25 | BT6: 26 | BU6: 27 | BV6: 28 | BW6: 29 | BX6: 30 | BY6: 31 | BZ6: 32 | CA6: 33 | CB6: 34 | CC6: 35
B7: 201506 | C7: 0 | D7: 0 | E7: 0 | F7: 0 | G7: 0 | H7: 0 | I7: 0 | J7: 0 | K7: 0 | L7: 0 | M7: 0 | N7: 0 | O7: 0 | P7: 0 | Q7: 0 | R7: 0 | S7: 0 | T7: 0 | U7: 0 | V7: 0 | W7: 0 | X7: 0 | Y7: 0 | Z7: 0 | AA7: 0 | AB7: 0 | AC7: 0 | AD7: 0 | AE7: 0 | AF7: 0 | AG7: 0 | AH7: 0 | AI7: 0 | AJ7: 0 | AK7: 0 | AT7: 201506 | AU7: 0 | AV7: 0 | AW7: 0 | AX7: 0 | AY7: 0 | AZ7: 0 | BA7: 0 | BB7: 0 | BC7: 0 | BD7: 0 | BE7: 0 | BF7: 0 | BG7: 0 | BH7: 0 | BI7: 0 | BJ7: 0 | BK7: 0 | BL7: 0 | BM7: 0 | BN7: 0 | BO7: 0 | BP7: 0 | BQ7: 0 | BR7: 0 | BS7: 0 | BT7: 0 | BU7: 0 | BV7: 0 | BW7: 0 | BX7: 0 | BY7: 0 | BZ7: 0 | CA7: 0 | CB7: 0 | CC7: 0
B8: 201509 | C8: 0 | D8: 0 | E8: 0 | F8: 0 | G8: 0 | H8: 0 | I8: 0 | J8: 0 | K8: 0 | L8: 0 | M8: 0 | N8: 0 | O8: 0 | P8: 0 | Q8: 0 | R8: 0 | S8: 0 | T8: 0 | U8: 0 | V8: 0 | W8: 0 | X8: 0 | Y8: 0 | Z8: 0 | AA8: 0 | AB8: 0 | AC8: 0 | AD8: 0 | AE8: 0 | AF8: 0 | AG8: 0 | AH8: 0 | AI8: 0 | AJ8: 0 | AT8: 201509 | AU8: 0 | AV8: 0 | AW8: 0 | AX8: 0 | AY8: 0 | AZ8: 0 | BA8: 0 | BB8: 0 | BC8: 0 | BD8: 0 | BE8: 0 | BF8: 0 | BG8: 0 | BH8: 0 | BI8: 0 | BJ8: 0 | BK8: 0 | BL8: 0 | BM8: 0 | BN8: 0 | BO8: 0 | BP8: 0 | BQ8: 0 | BR8: 0 | BS8: 0 | BT8: 0 | BU8: 0 | BV8: 0 | BW8: 0 | BX8: 0 | BY8: 0 | BZ8: 0 | CA8: 0 | CB8: 0
B9: 201512 | C9: 0 | D9: 0 | E9: 0 | F9: 0 | G9: 0 | H9: 0 | I9: 0 | J9: 0 | K9: 0 | L9: 0 | M9: 0 | N9: 0 | O9: 0 | P9: 0 | Q9: 0 | R9: 0 | S9: 0 | T9: 0 | U9: 0 | V9: 0 | W9: 0 | X9: 0 | Y9: 0 | Z9: 0 | AA9: 0 | AB9: 0 | AC9: 0 | AD9: 0 | AE9: 0 | AF9: 0 | AG9: 0 | AH9: 0 | AI9: 0 | AT9: 201512 | AU9: 0 | AV9: 0 | AW9: 0 | AX9: 0 | AY9: 0 | AZ9: 0 | BA9: 0 | BB9: 0 | BC9: 0 | BD9: 0 | BE9: 0 | BF9: 0 | BG9: 0 | BH9: 0 | BI9: 0 | BJ9: 0 | BK9: 0 | BL9: 0 | BM9: 0 | BN9: 0 | BO9: 0 | BP9: 0 | BQ9: 0 | BR9: 0 | BS9: 0 | BT9: 0 | BU9: 0 | BV9: 0 | BW9: 0 | BX9: 0 | BY9: 0 | BZ9: 0 | CA9: 0
B10: 201603 | C10: 0 | D10: 0 | E10: 0 | F10: 0 | G10: 0 | H10: 0 | I10: 0 | J10: 0 | K10: 0 | L10: 0 | M10: 0 | N10: 0 | O10: 0 | P10: 0 | Q10: 0 | R10: 0 | S10: 0 | T10: 0 | U10: 0 | V10: 0 | W10: 0 | X10: 0 | Y10: 0 | Z10: 0 | AA10: 0 | AB10: 0 | AC10: 0 | AD10: 0 | AE10: 0 | AF10: 0 | AG10: 0 | AH10: 0 | AT10: 201603 | AU10: 0 | AV10: 0 | AW10: 0 | AX10: 0 | AY10: 0 | AZ10: 0 | BA10: 0 | BB10: 0 | BC10: 0 | BD10: 0 | BE10: 0 | BF10: 0 | BG10: 0 | BH10: 0 | BI10: 0 | BJ10: 0 | BK10: 0 | BL10: 0 | BM10: 0 | BN10: 0 | BO10: 0 | BP10: 0 | BQ10: 0 | BR10: 0 | BS10: 0 | BT10: 0 | BU10: 0 | BV10: 0 | BW10: 0 | BX10: 0 | BY10: 0 | BZ10: 0
B11: 201606 | C11: 0 | D11: 0 | E11: 0 | F11: 0 | G11: 0 | H11: 0 | I11: 0 | J11: 0 | K11: 0 | L11: 0 | M11: 0 | N11: 0 | O11: 0 | P11: 0 | Q11: 0 | R11: 0 | S11: 0 | T11: 0 | U11: 0 | V11: 0 | W11: 0 | X11: 0 | Y11: 0 | Z11: 0 | AA11: 0 | AB11: 0 | AC11: 0 | AD11: 0 | AE11: 0 | AF11: 0 | AG11: 0 | AT11: 201606 | AU11: 0 | AV11: 0 | AW11: 0 | AX11: 0 | AY11: 0 | AZ11: 0 | BA11: 0 | BB11: 0 | BC11: 0 | BD11: 0 | BE11: 0 | BF11: 0 | BG11: 0 | BH11: 0 | BI11: 0 | BJ11: 0 | BK11: 0 | BL11: 0 | BM11: 0 | BN11: 0 | BO11: 0 | BP11: 0 | BQ11: 0 | BR11: 0 | BS11: 0 | BT11: 0 | BU11: 0 | BV11: 0 | BW11: 0 | BX11: 0 | BY11: 0
B12: 201609 | C12: 0 | D12: 0 | E12: 0 | F12: 0 | G12: 0 | H12: 0 | I12: 0 | J12: 0 | K12: 0 | L12: 0 | M12: 0 | N12: 0 | O12: 0 | P12: 0 | Q12: 0 | R12: 0 | S12: 0 | T12: 0 | U12: 0 | V12: 0 | W12: 0 | X12: 0 | Y12: 0 | Z12: 0 | AA12: 0 | AB12: 0 | AC12: 0 | AD12: 0 | AE12: 0 | AF12: 0 | AT12: 201609 | AU12: 0 | AV12: 0 | AW12: 0 | AX12: 0 | AY12: 0 | AZ12: 0 | BA12: 0 | BB12: 0 | BC12: 0 | BD12: 0 | BE12: 0 | BF12: 0 | BG12: 0 | BH12: 0 | BI12: 0 | BJ12: 0 | BK12: 0 | BL12: 0 | BM12: 0 | BN12: 0 | BO12: 0 | BP12: 0 | BQ12: 0 | BR12: 0 | BS12: 0 | BT12: 0 | BU12: 0 | BV12: 0 | BW12: 0 | BX12: 0
B13: 201612 | C13: 28000 | D13: 120081.42 | E13: 225081.42 | F13: 2047879.5 | G13: 5882335.3 | H13: 5882335.3 | I13: 5882335.3 | J13: 5882335.3 | K13: 5882335.3 | L13: 5882335.3 | M13: 5882335.3 | N13: 5882335.3 | O13: 5848635.3 | P13: 5848635.3 | Q13: 5848635.3 | R13: 5848635.3 | S13: 5846685.3 | T13: 5801185.3 | U13: 5697185.3 | V13: 5651685.3 | W13: 5651685.3 | X13: 5567185.3 | Y13: 5567185.3 | Z13: 5567185.3 | AA13: 5535985.3 | AB13: 5535985.3 | AC13: 5535985.3 | AD13: 5535985.3 | AE13: 5535985.3 | AT13: 201612 | AU13: 28000 | AV13: 120081.42 | AW13: 225081.42 | AX13: 2047879.5 | AY13: 5882335.3 | AZ13: 5882335.3 | BA13: 5882335.3 | BB13: 5882335.3 | BC13: 5882335.3 | BD13: 5882335.3 | BE13: 5882335.3 | BF13: 5882335.3 | BG13: 5848635.3 | BH13: 5848635.3 | BI13: 5848635.3 | BJ13: 5848635.3 | BK13: 5846685.3 | BL13: 5801185.3 | BM13: 5697185.3 | BN13: 5651685.3 | BO13: 5651685.3 | BP13: 5567185.3 | BQ13: 5567185.3 | BR13: 5567185.3 | BS13: 5535985.3 | BT13: 5535985.3 | BU13: 5535985.3 | BV13: 5535985.3 | BW13: 5535985.3
B14: 201703 | C14: 112000 | D14: 287000 | E14: 4690194.1 | F14: 7546009 | G14: 7546009 | H14: 7546009 | I14: 7823091.7 | J14: 7823091.7 | K14: 7823091.7 | L14: 7823091.7 | M14: 7823091.7 | N14: 7453768.4 | O14: 7453768.4 | P14: 7451818.4 | Q14: 7431018.4 | R14: 7417043.4 | S14: 7415093.4 | T14: 7413143.4 | U14: 7413143.4 | V14: 7413143.4 | W14: 7413143.4 | X14: 7413143.4 | Y14: 7330648.8 | Z14: 7285625.9 | AA14: 7259625.9 | AB14: 7253125.9 | AC14: 7253125.9 | AD14: 7252475.9 | AT14: 201703 | AU14: 112000 | AV14: 287000 | AW14: 4690194.1 | AX14: 7546009 | AY14: 7546009 | AZ14: 7546009 | BA14: 7823091.7 | BB14: 7823091.7 | BC14: 7823091.7 | BD14: 7823091.7 | BE14: 7823091.7 | BF14: 7453768.4 | BG14: 7453768.4 | BH14: 7451818.4 | BI14: 7431018.4 | BJ14: 7417043.4 | BK14: 7415093.4 | BL14: 7413143.4 | BM14: 7413143.4 | BN14: 7413143.4 | BO14: 7413143.4 | BP14: 7413143.4 | BQ14: 7330648.8 | BR14: 7285625.9 | BS14: 7259625.9 | BT14: 7253125.9 | BU14: 7253125.9 | BV14: 7252475.9
B15: 201706 | C15: 0 | D15: 0 | E15: 391799.12 | F15: 391799.12 | G15: 391799.12 | H15: 391799.12 | I15: 391799.12 | J15: 391799.12 | K15: 391799.12 | L15: 391799.12 | M15: 234464.28 | N15: 234464.28 | O15: 234464.28 | P15: 234464.28 | Q15: 234464.28 | R15: 234464.28 | S15: 234464.28 | T15: 234464.28 | U15: 234464.28 | V15: 234464.28 | W15: 234464.28 | X15: 234464.28 | Y15: 150464.28 | Z15: 150464.28 | AA15: 150464.28 | AB15: 150464.28 | AC15: 150464.28 | AT15: 201706 | AU15: 0 | AV15: 0 | AW15: 391799.12 | AX15: 391799.12 | AY15: 391799.12 | AZ15: 391799.12 | BA15: 391799.12 | BB15: 391799.12 | BC15: 391799.12 | BD15: 391799.12 | BE15: 234464.28 | BF15: 234464.28 | BG15: 234464.28 | BH15: 234464.28 | BI15: 234464.28 | BJ15: 234464.28 | BK15: 234464.28 | BL15: 234464.28 | BM15: 234464.28 | BN15: 234464.28 | BO15: 234464.28 | BP15: 234464.28 | BQ15: 150464.28 | BR15: 150464.28 | BS15: 150464.28 | BT15: 150464.28 | BU15: 150464.28
B16: 201709 | C16: 0 | D16: 0 | E16: 0 | F16: 0 | G16: 0 | H16: 0 | I16: 0 | J16: 0 | K16: 0 | L16: 0 | M16: 0 | N16: 0 | O16: 0 | P16: 0 | Q16: 0 | R16: 0 | S16: 0 | T16: 0 | U16: 0 | V16: 0 | W16: 0 | X16: 0 | Y16: 0 | Z16: 0 | AA16: 0 | AB16: 0 | AT16: 201709 | AU16: 0 | AV16: 0 | AW16: 0 | AX16: 0 | AY16: 0 | AZ16: 0 | BA16: 0 | BB16: 0 | BC16: 0 | BD16: 0 | BE16: 0 | BF16: 0 | BG16: 0 | BH16: 0 | BI16: 0 | BJ16: 0 | BK16: 0 | BL16: 0 | BM16: 0 | BN16: 0 | BO16: 0 | BP16: 0 | BQ16: 0 | BR16: 0 | BS16: 0 | BT16: 0
B17: 201712 | C17: 0 | D17: 0 | E17: 0 | F17: 2195522 | G17: 2352066.9 | H17: 2352066.9 | I17: 2352066.9 | J17: 2352066.9 | K17: 2777603.1 | L17: 2777603.1 | M17: 2777603.1 | N17: 2773138.1 | O17: 2773138.1 | P17: 2773138.1 | Q17: 2773138.1 | R17: 2773138.1 | S17: 2690074.6 | T17: 2725074.6 | U17: 2725074.6 | V17: 2809074.6 | W17: 2809074.6 | X17: 2809074.6 | Y17: 3849274.6 | Z17: 3849274.6 | AA17: 3812069.3 | AT17: 201712 | AU17: 0 | AV17: 0 | AW17: 0 | AX17: 2195522 | AY17: 2352066.9 | AZ17: 2352066.9 | BA17: 2352066.9 | BB17: 2352066.9 | BC17: 2777603.1 | BD17: 2777603.1 | BE17: 2777603.1 | BF17: 2773138.1 | BG17: 2773138.1 | BH17: 2773138.1 | BI17: 2773138.1 | BJ17: 2773138.1 | BK17: 2690074.6 | BL17: 2725074.6 | BM17: 2725074.6 | BN17: 2809074.6 | BO17: 2809074.6 | BP17: 2809074.6 | BQ17: 3849274.6 | BR17: 3849274.6 | BS17: 3812069.3
B18: 201803 | C18: 0 | D18: 0 | E18: 0 | F18: 294740.78 | G18: 294740.78 | H18: 294740.78 | I18: 294740.78 | J18: 1923623.1 | K18: 1923623.1 | L18: 1923623.1 | M18: 2037123.1 | N18: 2019498.1 | O18: 2019498.1 | P18: 2019498.1 | Q18: 2019498.1 | R18: 2019498.1 | S18: 2019498.1 | T18: 2019498.1 | U18: 2019498.1 | V18: 2019498.1 | W18: 2019498.1 | X18: 2019498.1 | Y18: 2019498.1 | Z18: 1957915.8 | AT18: 201803 | AU18: 0 | AV18: 0 | AW18: 0 | AX18: 294740.78 | AY18: 294740.78 | AZ18: 294740.78 | BA18: 294740.78 | BB18: 1923623.1 | BC18: 1923623.1 | BD18: 1923623.1 | BE18: 2037123.1 | BF18: 2019498.1 | BG18: 2019498.1 | BH18: 2019498.1 | BI18: 2019498.1 | BJ18: 2019498.1 | BK18: 2019498.1 | BL18: 2019498.1 | BM18: 2019498.1 | BN18: 2019498.1 | BO18: 2019498.1 | BP18: 2019498.1 | BQ18: 2019498.1 | BR18: 1957915.8
B19: 201806 | C19: 0 | D19: 0 | E19: 551624.94 | F19: 551624.94 | G19: 551624.94 | H19: 551624.94 | I19: 1637911.2 | J19: 1637911.2 | K19: 1637911.2 | L19: 1813555.4 | M19: 1698092.9 | N19: 1698092.9 | O19: 1698092.9 | P19: 1698092.9 | Q19: 1698092.9 | R19: 1698092.9 | S19: 1698092.9 | T19: 1698092.9 | U19: 1698092.9 | V19: 1698092.9 | W19: 1698092.9 | X19: 1698092.9 | Y19: 1698092.9 | AT19: 201806 | AU19: 0 | AV19: 0 | AW19: 551624.94 | AX19: 551624.94 | AY19: 551624.94 | AZ19: 551624.94 | BA19: 1637911.2 | BB19: 1637911.2 | BC19: 1637911.2 | BD19: 1813555.4 | BE19: 1698092.9 | BF19: 1698092.9 | BG19: 1698092.9 | BH19: 1698092.9 | BI19: 1698092.9 | BJ19: 1698092.9 | BK19: 1698092.9 | BL19: 1698092.9 | BM19: 1698092.9 | BN19: 1698092.9 | BO19: 1698092.9 | BP19: 1698092.9 | BQ19: 1698092.9
B20: 201809 | C20: 0 | D20: 0 | E20: 0 | F20: 371717.97 | G20: 371717.97 | H20: 631946.09 | I20: 839035.97 | J20: 839035.97 | K20: 839035.97 | L20: 914550.97 | M20: 914550.97 | N20: 914550.97 | O20: 914550.97 | P20: 839634.47 | Q20: 839634.47 | R20: 839634.47 | S20: 839634.47 | T20: 839634.47 | U20: 839634.47 | V20: 839634.47 | W20: 839634.47 | X20: 837918.11 | AT20: 201809 | AU20: 0 | AV20: 0 | AW20: 0 | AX20: 371717.97 | AY20: 371717.97 | AZ20: 631946.09 | BA20: 839035.97 | BB20: 839035.97 | BC20: 839035.97 | BD20: 914550.97 | BE20: 914550.97 | BF20: 914550.97 | BG20: 914550.97 | BH20: 839634.47 | BI20: 839634.47 | BJ20: 839634.47 | BK20: 839634.47 | BL20: 839634.47 | BM20: 839634.47 | BN20: 839634.47 | BO20: 839634.47 | BP20: 837918.11
B21: 201812 | C21: 0 | D21: 0 | E21: 1235098.7 | F21: 1235098.7 | G21: 1637833.7 | H21: 1711689.6 | I21: 1741102.8 | J21: 1911664.4 | K21: 1889093.7 | L21: 1889093.7 | M21: 1889093.7 | N21: 1889093.7 | O21: 1889093.7 | P21: 1889093.7 | Q21: 1889093.7 | R21: 1889093.7 | S21: 1889093.7 | T21: 1889093.7 | U21: 1889093.7 | V21: 1889093.7 | W21: 1889093.7 | AT21: 201812 | AU21: 0 | AV21: 0 | AW21: 1235098.7 | AX21: 1235098.7 | AY21: 1637833.7 | AZ21: 1711689.6 | BA21: 1741102.8 | BB21: 1911664.4 | BC21: 1889093.7 | BD21: 1889093.7 | BE21: 1889093.7 | BF21: 1889093.7 | BG21: 1889093.7 | BH21: 1889093.7 | BI21: 1889093.7 | BJ21: 1889093.7 | BK21: 1889093.7 | BL21: 1889093.7 | BM21: 1889093.7 | BN21: 1889093.7 | BO21: 1889093.7
B22: 201903 | C22: 0 | D22: 0 | E22: 1308755.8 | F22: 2298657.5 | G22: 2298657.5 | H22: 2298657.5 | I22: 2869761.6 | J22: 2947592.9 | K22: 2987004.1 | L22: 2987004.1 | M22: 2987004.1 | N22: 3891350 | O22: 3891350 | P22: 3891350 | Q22: 3891350 | R22: 3890650 | S22: 3890650 | T22: 3890650 | U22: 3890650 | V22: 3890650 | AT22: 201903 | AU22: 0 | AV22: 0 | AW22: 1308755.8 | AX22: 2298657.5 | AY22: 2298657.5 | AZ22: 2298657.5 | BA22: 2869761.6 | BB22: 2947592.9 | BC22: 2987004.1 | BD22: 2987004.1 | BE22: 2987004.1 | BF22: 3891350 | BG22: 3891350 | BH22: 3891350 | BI22: 3891350 | BJ22: 3890650 | BK22: 3890650 | BL22: 3890650 | BM22: 3890650 | BN22: 3890650
B23: 201906 | C23: 0 | D23: 0 | E23: 0 | F23: 0 | G23: 0 | H23: 0 | I23: 0 | J23: 0 | K23: 0 | L23: 0 | M23: 0 | N23: 0 | O23: 0 | P23: 0 | Q23: 0 | R23: 0 | S23: 0 | T23: 0 | U23: 0 | AT23: 201906 | AU23: 0 | AV23: 0 | AW23: 0 | AX23: 0 | AY23: 0 | AZ23: 0 | BA23: 0 | BB23: 0 | BC23: 0 | BD23: 0 | BE23: 0 | BF23: 0 | BG23: 0 | BH23: 0 | BI23: 0 | BJ23: 0 | BK23: 0 | BL23: 0 | BM23: 0
B24: 201909 | C24: 0 | D24: 1438260.9 | E24: 1438260.9 | F24: 1438260.9 | G24: 1438260.9 | H24: 1123778.3 | I24: 1123778.3 | J24: 1117278.3 | K24: 1117278.3 | L24: 1117278.3 | M24: 1117278.3 | N24: 1117278.3 | O24: 1117278.3 | P24: 1117278.3 | Q24: 1117278.3 | R24: 1117278.3 | S24: 1117278.3 | T24: 1117278.3 | AT24: 201909 | AU24: 0 | AV24: 1438260.9 | AW24: 1438260.9 | AX24: 1438260.9 | AY24: 1438260.9 | AZ24: 1123778.3 | BA24: 1123778.3 | BB24: 1117278.3 | BC24: 1117278.3 | BD24: 1117278.3 | BE24: 1117278.3 | BF24: 1117278.3 | BG24: 1117278.3 | BH24: 1117278.3 | BI24: 1117278.3 | BJ24: 1117278.3 | BK24: 1117278.3 | BL24: 1117278.3
B25: 201912 | C25: 0 | D25: 0 | E25: 0 | F25: 0 | G25: 0 | H25: 0 | I25: 0 | J25: 0 | K25: 0 | L25: 0 | M25: 0 | N25: 0 | O25: 0 | P25: 0 | Q25: 0 | R25: 0 | S25: 0 | AT25: 201912 | AU25: 0 | AV25: 0 | AW25: 0 | AX25: 0 | AY25: 0 | AZ25: 0 | BA25: 0 | BB25: 0 | BC25: 0 | BD25: 0 | BE25: 0 | BF25: 0 | BG25: 0 | BH25: 0 | BI25: 0 | BJ25: 0 | BK25: 0
B26: 202003 | C26: 0 | D26: 0 | E26: 0 | F26: 0 | G26: 0 | H26: 0 | I26: 0 | J26: 0 | K26: 250000 | L26: 250000 | M26: 250000 | N26: 250000 | O26: 250000 | P26: 250000 | Q26: 250000 | R26: 250000 | AT26: 202003 | AU26: 0 | AV26: 0 | AW26: 0 | AX26: 0 | AY26: 0 | AZ26: 0 | BA26: 0 | BB26: 0 | BC26: 250000 | BD26: 250000 | BE26: 250000 | BF26: 250000 | BG26: 250000 | BH26: 250000 | BI26: 250000 | BJ26: 250000
B27: 202006 | C27: 0 | D27: 0 | E27: 0 | F27: 0 | G27: 0 | H27: 0 | I27: 0 | J27: 0 | K27: 0 | L27: 0 | M27: 0 | N27: 0 | O27: 0 | P27: 0 | Q27: 0 | AT27: 202006 | AU27: 0 | AV27: 0 | AW27: 0 | AX27: 0 | AY27: 0 | AZ27: 0 | BA27: 0 | BB27: 0 | BC27: 0 | BD27: 0 | BE27: 0 | BF27: 0 | BG27: 0 | BH27: 0 | BI27: 0
B28: 202009 | C28: 0 | D28: 0 | E28: 0 | F28: 0 | G28: 0 | H28: 0 | I28: 900000 | J28: 900000 | K28: 900000 | L28: 900000 | M28: 900000 | N28: 900000 | O28: 900000 | P28: 900000 | AT28: 202009 | AU28: 0 | AV28: 0 | AW28: 0 | AX28: 0 | AY28: 0 | AZ28: 0 | BA28: 900000 | BB28: 900000 | BC28: 900000 | BD28: 900000 | BE28: 900000 | BF28: 900000 | BG28: 900000 | BH28: 900000
B29: 202012 | C29: 0 | D29: 0 | E29: 271710.74 | F29: 271710.74 | G29: 271710.74 | H29: 271710.74 | I29: 271710.74 | J29: 271710.74 | K29: 254398.57 | L29: 254398.57 | M29: 174398.57 | N29: 94398.57 | O29: 44398.57 | AT29: 202012 | AU29: 0 | AV29: 0 | AW29: 271710.74 | AX29: 271710.74 | AY29: 271710.74 | AZ29: 271710.74 | BA29: 271710.74 | BB29: 271710.74 | BC29: 254398.57 | BD29: 254398.57 | BE29: 174398.57 | BF29: 94398.57 | BG29: 44398.57
B30: 202103 | C30: 0 | D30: 0 | E30: 0 | F30: 1758330.8 | G30: 1758330.8 | H30: 1758330.8 | I30: 1758330.8 | J30: 1758330.8 | K30: 1758330.8 | L30: 1758330.8 | M30: 1758330.8 | N30: 1758330.8 | AT30: 202103 | AU30: 0 | AV30: 0 | AW30: 0 | AX30: 1758330.8 | AY30: 1758330.8 | AZ30: 1758330.8 | BA30: 1758330.8 | BB30: 1758330.8 | BC30: 1758330.8 | BD30: 1758330.8 | BE30: 1758330.8 | BF30: 1758330.8
B31: 202106 | C31: 0 | D31: 0 | E31: 0 | F31: 0 | G31: 0 | H31: 0 | I31: 0 | J31: 0 | K31: 0 | L31: 0 | M31: 0 | AT31: 202106 | AU31: 0 | AV31: 0 | AW31: 0 | AX31: 0 | AY31: 0 | AZ31: 0 | BA31: 0 | BB31: 0 | BC31: 0 | BD31: 0 | BE31: 0
B32: 202109 | C32: 0 | D32: 0 | E32: 0 | F32: 0 | G32: 0 | H32: 0 | I32: 0 | J32: 0 | K32: 0 | L32: 0 | AT32: 202109 | AU32: 0 | AV32: 0 | AW32: 0 | AX32: 0 | AY32: 0 | AZ32: 0 | BA32: 0 | BB32: 0 | BC32: 0 | BD32: 0
B33: 202112 | C33: 0 | D33: 0 | E33: 0 | F33: 0 | G33: 0 | H33: 0 | I33: 0 | J33: 0 | K33: 0 | AT33: 202112 | AU33: 0 | AV33: 0 | AW33: 0 | AX33: 0 | AY33: 0 | AZ33: 0 | BA33: 0 | BB33: 0 | BC33: 0
B34: 202203 | C34: 0 | D34: 0 | E34: 0 | F34: 0 | G34: 0 | H34: 0 | I34: 0 | J34: 0 | AT34: 202203 | AU34: 0 | AV34: 0 | AW34: 0 | AX34: 0 | AY34: 0 | AZ34: 0 | BA34: 0 | BB34: 0
B35: 202206 | C35: 0 | D35: 0 | E35: 0 | F35: 0 | G35: 0 | H35: 0 | I35: 0 | AT35: 202206 | AU35: 0 | AV35: 0 | AW35: 0 | AX35: 0 | AY35: 0 | AZ35: 0 | BA35: 0
B36: 202209 | C36: 0 | D36: 0 | E36: 0 | F36: 0 | G36: 0 | H36: 0 | AT36: 202209 | AU36: 0 | AV36: 0 | AW36: 0 | AX36: 0 | AY36: 0 | AZ36: 0
B37: 202212 | C37: 0 | D37: 0 | E37: 0 | F37: 0 | G37: 0 | AT37: 202212 | AU37: 0 | AV37: 0 | AW37: 0 | AX37: 0 | AY37: 0
B38: 202303 | C38: 0 | D38: 0 | E38: 0 | F38: 0 | AT38: 202303 | AU38: 0 | AV38: 0 | AW38: 0 | AX38: 0
B39: 202306 | C39: 0 | D39: 0 | E39: 0 | AT39: 202306 | AU39: 0 | AV39: 0 | AW39: 0
B40: 202309 | C40: 0 | D40: 0 | AT40: 202309 | AU40: 0 | AV40: 0
B41: 202312 | C41: 0 | AT41: 202312 | AU41: 0
...

Sheet 财产险
B2: 黄色底格要求可自行填写或输入公式 | AX2: 黄色底格要求可自行填写或输入公式 | CP2: 黄色底格要求可自行填写或输入公式
B3: 再保前 | AX3: 再保后 | CP3: 再保后
B4: 累计已决三角形 | AJ4: 单位：人民币元 | AX4: 累计已决三角形 | CF4: 单位：人民币元 | CP4: 累计已决三角形 | DX4: 单位：人民币元
B5: 事故月份 | C5: 进展区间 | AX5: 事故月份 | AY5: 进展区间 | CP5: 事故月份 | CQ5: 进展区间
C6: 1 | D6: 2 | E6: 3 | F6: 4 | G6: 5 | H6: 6 | I6: 7 | J6: 8 | K6: 9 | L6: 10 | M6: 11 | N6: 12 | O6: 13 | P6: 14 | Q6: 15 | R6: 16 | S6: 17 | T6: 18 | U6: 19 | V6: 20 | W6: 21 | X6: 22 | Y6: 23 | Z6: 24 | AA6: 25 | AB6: 26 | AC6: 27 | AD6: 28 | AE6: 29 | AF6: 30 | AG6: 31 | AH6: 32 | AI6: 33 | AJ6: 34 | AK6: 35 | AY6: 1 | AZ6: 2 | BA6: 3 | BB6: 4 | BC6: 5 | BD6: 6 | BE6: 7 | BF6: 8 | BG6: 9 | BH6: 10 | BI6: 11 | BJ6: 12 | BK6: 13 | BL6: 14 | BM6: 15 | BN6: 16 | BO6: 17 | BP6: 18 | BQ6: 19 | BR6: 20 | BS6: 21 | BT6: 22 | BU6: 23 | BV6: 24 | BW6: 25 | BX6: 26 | BY6: 27 | BZ6: 28 | CA6: 29 | CB6: 30 | CC6: 31 | CD6: 32 | CE6: 33 | CF6: 34 | CG6: 35 | CQ6: 1 | CR6: 2 | CS6: 3 | CT6: 4 | CU6: 5 | CV6: 6 | CW6: 7 | CX6: 8 | CY6: 9 | CZ6: 10 | DA6: 11 | DB6: 12 | DC6: 13 | DD6: 14 | DE6: 15 | DF6: 16 | DG6: 17 | DH6: 18 | DI6: 19 | DJ6: 20 | DK6: 21 | DL6: 22 | DM6: 23 | DN6: 24 | DO6: 25 | DP6: 26 | DQ6: 27 | DR6: 28 | DS6: 29 | DT6: 30 | DU6: 31 | DV6: 32 | DW6: 33 | DX6: 34 | DY6: 35
B7: 201606 | C7: 73450 | D7: 506213 | E7: 513613 | F7: 514288 | G7: 514888 | H7: 514888 | I7: 514888 | J7: 514888 | K7: 514888 | L7: 514888 | M7: 514888 | N7: 514888 | O7: 514888 | P7: 514888 | Q7: 514888 | R7: 514888 | S7: 514888 | T7: 514888 | U7: 514888 | V7: 514888 | W7: 514888 | X7: 514888 | Y7: 514888 | Z7: 514888 | AA7: 514888 | AB7: 514888 | AC7: 514888 | AD7: 514888 | AE7: 514888 | AF7: 514888 | AG7: 514888 | AH7: 514888 | AI7: 514888 | AJ7: 514888 | AK7: 514888 | AX7: 201606 | AY7: 73450 | AZ7: 506213 | BA7: 513613 | BB7: 514288 | BC7: 514888 | BD7: 514888 | BE7: 514888 | BF7: 514888 | BG7: 514888 | BH7: 514888 | BI7: 514888 | BJ7: 514888 | BK7: 514888 | BL7: 514888 | BM7: 514888 | BN7: 514888 | BO7: 514888 | BP7: 514888 | BQ7: 514888 | BR7: 514888 | BS7: 514888 | BT7: 514888 | BU7: 514888 | BV7: 514888 | BW7: 514888 | BX7: 514888 | BY7: 514888 | BZ7: 514888 | CA7: 514888 | CB7: 514888 | CC7: 514888 | CD7: 514888 | CE7: 514888 | CF7: 514888 | CG7: 514888 | CP7: 201506 | CQ7: 0 | CR7: 0 | CS7: 0 | CT7: 0 | CU7: 0 | CV7: 0 | CW7: 0 | CX7: 0 | CY7: 0 | CZ7: 0 | DA7: 0 | DB7: 0 | DC7: 0 | DD7: 0 | DE7: 0 | DF7: 0 | DG7: 0 | DH7: 0 | DI7: 0 | DJ7: 0 | DK7: 0 | DL7: 0 | DM7: 0 | DN7: 0 | DO7: 0 | DP7: 0 | DQ7: 0 | DR7: 0 | DS7: 0 | DT7: 0 | DU7: 0 | DV7: 0 | DW7: 0 | DX7: 0 | DY7: 0
B8: 201609 | C8: 90324 | D8: 95204 | E8: 95204 | F8: 106004 | G8: 155104 | H8: 164564 | I8: 164564 | J8: 168364 | K8: 168364 | L8: 168364 | M8: 168364 | N8: 168364 | O8: 168364 | P8: 168364 | Q8: 168364 | R8: 168364 | S8: 168364 | T8: 168364 | U8: 168364 | V8: 168364 | W8: 168364 | X8: 168364 | Y8: 168364 | Z8: 168364 | AA8: 168364 | AB8: 168364 | AC8: 168364 | AD8: 168364 | AE8: 168364 | AF8: 168364 | AG8: 168364 | AH8: 168364 | AI8: 168364 | AJ8: 168364 | AX8: 201609 | AY8: 90324 | AZ8: 95204 | BA8: 95204 | BB8: 106004 | BC8: 155104 | BD8: 164564 | BE8: 164564 | BF8: 168364 | BG8: 168364 | BH8: 168364 | BI8: 168364 | BJ8: 168364 | BK8: 168364 | BL8: 168364 | BM8: 168364 | BN8: 168364 | BO8: 168364 | BP8: 168364 | BQ8: 168364 | BR8: 168364 | BS8: 168364 | BT8: 168364 | BU8: 168364 | BV8: 168364 | BW8: 168364 | BX8: 168364 | BY8: 168364 | BZ8: 168364 | CA8: 168364 | CB8: 168364 | CC8: 168364 | CD8: 168364 | CE8: 168364 | CF8: 168364 | CP8: 201509 | CQ8: 0 | CR8: 0 | CS8: 0 | CT8: 0 | CU8: 0 | CV8: 0 | CW8: 0 | CX8: 0 | CY8: 0 | CZ8: 0 | DA8: 0 | DB8: 0 | DC8: 0 | DD8: 0 | DE8: 0 | DF8: 0 | DG8: 0 | DH8: 0 | DI8: 0 | DJ8: 0 | DK8: 0 | DL8: 0 | DM8: 0 | DN8: 0 | DO8: 0 | DP8: 0 | DQ8: 0 | DR8: 0 | DS8: 0 | DT8: 0 | DU8: 0 | DV8: 0 | DW8: 0 | DX8: 0
B9: 201612 | C9: 1650 | D9: 77050 | E9: 187823.18 | F9: 205103.18 | G9: 205103.18 | H9: 211903.18 | I9: 211903.18 | J9: 211903.18 | K9: 211903.18 | L9: 211903.18 | M9: 211903.18 | N9: 211903.18 | O9: 211903.18 | P9: 211903.18 | Q9: 211903.18 | R9: 211903.18 | S9: 211903.18 | T9: 211903.18 | U9: 211903.18 | V9: 211903.18 | W9: 211903.18 | X9: 211903.18 | Y9: 211903.18 | Z9: 211903.18 | AA9: 211903.18 | AB9: 211903.18 | AC9: 211903.18 | AD9: 211903.18 | AE9: 211903.18 | AF9: 211903.18 | AG9: 211903.18 | AH9: 211903.18 | AI9: 211903.18 | AX9: 201612 | AY9: 1650 | AZ9: 77050 | BA9: 187823.18 | BB9: 205103.18 | BC9: 205103.18 | BD9: 211903.18 | BE9: 211903.18 | BF9: 211903.18 | BG9: 211903.18 | BH9: 211903.18 | BI9: 211903.18 | BJ9: 211903.18 | BK9: 211903.18 | BL9: 211903.18 | BM9: 211903.18 | BN9: 211903.18 | BO9: 211903.18 | BP9: 211903.18 | BQ9: 211903.18 | BR9: 211903.18 | BS9: 211903.18 | BT9: 211903.18 | BU9: 211903.18 | BV9: 211903.18 | BW9: 211903.18 | BX9: 211903.18 | BY9: 211903.18 | BZ9: 211903.18 | CA9: 211903.18 | CB9: 211903.18 | CC9: 211903.18 | CD9: 211903.18 | CE9: 211903.18 | CP9: 201512 | CQ9: 0 | CR9: 0 | CS9: 0 | CT9: 0 | CU9: 0 | CV9: 0 | CW9: 0 | CX9: 0 | CY9: 0 | CZ9: 0 | DA9: 0 | DB9: 0 | DC9: 0 | DD9: 0 | DE9: 0 | DF9: 0 | DG9: 0 | DH9: 0 | DI9: 0 | DJ9: 0 | DK9: 0 | DL9: 0 | DM9: 0 | DN9: 0 | DO9: 0 | DP9: 0 | DQ9: 0 | DR9: 0 | DS9: 0 | DT9: 0 | DU9: 0 | DV9: 0 | DW9: 0
B10: 201703 | C10: 171306 | D10: 441166 | E10: 450166 | F10: 450166 | G10: 450166 | H10: 450166 | I10: 450166 | J10: 450166 | K10: 450902.2 | L10: 456072.49 | M10: 456072.49 | N10: 456072.49 | O10: 456072.49 | P10: 456072.49 | Q10: 456072.49 | R10: 456072.49 | S10: 456072.49 | T10: 456072.49 | U10: 456072.49 | V10: 456072.49 | W10: 456072.49 | X10: 456072.49 | Y10: 456072.49 | Z10: 456072.49 | AA10: 456072.49 | AB10: 456072.49 | AC10: 456072.49 | AD10: 456072.49 | AE10: 456072.49 | AF10: 456072.49 | AG10: 456072.49 | AH10: 456072.49 | AX10: 201703 | AY10: 171306 | AZ10: 441166 | BA10: 450166 | BB10: 450166 | BC10: 450166 | BD10: 450166 | BE10: 450166 | BF10: 450166 | BG10: 450902.2 | BH10: 456072.49 | BI10: 456072.49 | BJ10: 456072.49 | BK10: 456072.49 | BL10: 456072.49 | BM10: 456072.49 | BN10: 456072.49 | BO10: 456072.49 | BP10: 456072.49 | BQ10: 456072.49 | BR10: 456072.49 | BS10: 456072.49 | BT10: 456072.49 | BU10: 456072.49 | BV10: 456072.49 | BW10: 456072.49 | BX10: 456072.49 | BY10: 456072.49 | BZ10: 456072.49 | CA10: 456072.49 | CB10: 456072.49 | CC10: 456072.49 | CD10: 456072.49 | CP10: 201603 | CQ10: 0 | CR10: 0 | CS10: 0 | CT10: 0 | CU10: 0 | CV10: 0 | CW10: 0 | CX10: 0 | CY10: 0 | CZ10: 0 | DA10: 0 | DB10: 0 | DC10: 0 | DD10: 0 | DE10: 0 | DF10: 0 | DG10: 0 | DH10: 0 | DI10: 0 | DJ10: 0 | DK10: 0 | DL10: 0 | DM10: 0 | DN10: 0 | DO10: 0 | DP10: 0 | DQ10: 0 | DR10: 0 | DS10: 0 | DT10: 0 | DU10: 0 | DV10: 0
B11: 201706 | C11: 437596.4 | D11: 1098565.3 | E11: 1382869 | F11: 1486179.4 | G11: 1486179.4 | H11: 1486179.4 | I11: 1486179.4 | J11: 1486179.4 | K11: 1486179.4 | L11: 1486179.4 | M11: 1486179.4 | N11: 1486179.4 | O11: 1486179.4 | P11: 1486179.4 | Q11: 1486179.4 | R11: 1486179.4 | S11: 1486179.4 | T11: 1486179.4 | U11: 1486179.4 | V11: 1486179.4 | W11: 1486179.4 | X11: 1486179.4 | Y11: 1486179.4 | Z11: 1486179.4 | AA11: 1486179.4 | AB11: 1486179.4 | AC11: 1486179.4 | AD11: 1486179.4 | AE11: 1486179.4 | AF11: 1486179.4 | AG11: 1486179.4 | AX11: 201706 | AY11: 437596.4 | AZ11: 1098565.3 | BA11: 1382869 | BB11: 1486179.4 | BC11: 1486179.4 | BD11: 1486179.4 | BE11: 1486179.4 | BF11: 1486179.4 | BG11: 1486179.4 | BH11: 1486179.4 | BI11: 1486179.4 | BJ11: 1486179.4 | BK11: 1486179.4 | BL11: 1486179.4 | BM11: 1486179.4 | BN11: 1486179.4 | BO11: 1486179.4 | BP11: 1486179.4 | BQ11: 1486179.4 | BR11: 1486179.4 | BS11: 1486179.4 | BT11: 1486179.4 | BU11: 1486179.4 | BV11: 1486179.4 | BW11: 1486179.4 | BX11: 1486179.4 | BY11: 1486179.4 | BZ11: 1486179.4 | CA11: 1486179.4 | CB11: 1486179.4 | CC11: 1486179.4 | CP11: 201606 | CQ11: 73450 | CR11: 506213 | CS11: 513613 | CT11: 514288 | CU11: 514888 | CV11: 514888 | CW11: 514888 | CX11: 514888 | CY11: 514888 | CZ11: 514888 | DA11: 514888 | DB11: 514888 | DC11: 514888 | DD11: 514888 | DE11: 514888 | DF11: 514888 | DG11: 514888 | DH11: 514888 | DI11: 514888 | DJ11: 514888 | DK11: 514888 | DL11: 514888 | DM11: 514888 | DN11: 514888 | DO11: 514888 | DP11: 514888 | DQ11: 514888 | DR11: 514888 | DS11: 514888 | DT11: 514888 | DU11: 514888
B12: 201709 | C12: 898347.3 | D12: 2079772 | E12: 2189337.1 | F12: 2189337.1 | G12: 2189337.1 | H12: 2189337.1 | I12: 2189337.1 | J12: 2189337.1 | K12: 2189337.1 | L12: 2189337.1 | M12: 2189337.1 | N12: 2189337.1 | O12: 2189337.1 | P12: 2189337.1 | Q12: 2189337.1 | R12: 2189337.1 | S12: 2189337.1 | T12: 2189337.1 | U12: 2189337.1 | V12: 2189337.1 | W12: 2189337.1 | X12: 2189337.1 | Y12: 2189337.1 | Z12: 2189337.1 | AA12: 2189337.1 | AB12: 2189337.1 | AC12: 2189337.1 | AD12: 2189337.1 | AE12: 2189337.1 | AF12: 2189337.1 | AX12: 201709 | AY12: 898347.3 | AZ12: 2079772 | BA12: 2189337.1 | BB12: 2189337.1 | BC12: 2189337.1 | BD12: 2189337.1 | BE12: 2189337.1 | BF12: 2189337.1 | BG12: 2189337.1 | BH12: 2189337.1 | BI12: 2189337.1 | BJ12: 2189337.1 | BK12: 2189337.1 | BL12: 2189337.1 | BM12: 2189337.1 | BN12: 2189337.1 | BO12: 2189337.1 | BP12: 2189337.1 | BQ12: 2189337.1 | BR12: 2189337.1 | BS12: 2189337.1 | BT12: 2189337.1 | BU12: 2189337.1 | BV12: 2189337.1 | BW12: 2189337.1 | BX12: 2189337.1 | BY12: 2189337.1 | BZ12: 2189337.1 | CA12: 2189337.1 | CB12: 2189337.1 | CP12: 201609 | CQ12: 90324 | CR12: 95204 | CS12: 95204 | CT12: 106004 | CU12: 155104 | CV12: 164564 | CW12: 164564 | CX12: 168364 | CY12: 168364 | CZ12: 168364 | DA12: 168364 | DB12: 168364 | DC12: 168364 | DD12: 168364 | DE12: 168364 | DF12: 168364 | DG12: 168364 | DH12: 168364 | DI12: 168364 | DJ12: 168364 | DK12: 168364 | DL12: 168364 | DM12: 168364 | DN12: 168364 | DO12: 168364 | DP12: 168364 | DQ12: 168364 | DR12: 168364 | DS12: 168364 | DT12: 168364
B13: 201712 | C13: 608349.87 | D13: 962919.52 | E13: 1017800.5 | F13: 1074284.8 | G13: 1079397.1 | H13: 1079397.1 | I13: 1079397.1 | J13: 1081997.1 | K13: 1081997.1 | L13: 1081997.1 | M13: 1087740.8 | N13: 1087740.8 | O13: 1087740.8 | P13: 1087740.8 | Q13: 1087740.8 | R13: 1087740.8 | S13: 1087740.8 | T13: 1087740.8 | U13: 1087740.8 | V13: 1087740.8 | W13: 1087740.8 | X13: 1087740.8 | Y13: 1087740.8 | Z13: 1087740.8 | AA13: 1087740.8 | AB13: 1087740.8 | AC13: 1087740.8 | AD13: 1087740.8 | AE13: 1087740.8 | AX13: 201712 | AY13: 608349.87 | AZ13: 962919.52 | BA13: 1017800.5 | BB13: 1074284.8 | BC13: 1079397.1 | BD13: 1079397.1 | BE13: 1079397.1 | BF13: 1081997.1 | BG13: 1081997.1 | BH13: 1081997.1 | BI13: 1087740.8 | BJ13: 1087740.8 | BK13: 1087740.8 | BL13: 1087740.8 | BM13: 1087740.8 | BN13: 1087740.8 | BO13: 1087740.8 | BP13: 1087740.8 | BQ13: 1087740.8 | BR13: 1087740.8 | BS13: 1087740.8 | BT13: 1087740.8 | BU13: 1087740.8 | BV13: 1087740.8 | BW13: 1087740.8 | BX13: 1087740.8 | BY13: 1087740.8 | BZ13: 1087740.8 | CA13: 1087740.8 | CP13: 201612 | CQ13: 1650 | CR13: 77050 | CS13: 187823.18 | CT13: 205103.18 | CU13: 205103.18 | CV13: 211903.18 | CW13: 211903.18 | CX13: 211903.18 | CY13: 211903.18 | CZ13: 211903.18 | DA13: 211903.18 | DB13: 211903.18 | DC13: 211903.18 | DD13: 211903.18 | DE13: 211903.18 | DF13: 211903.18 | DG13: 211903.18 | DH13: 211903.18 | DI13: 211903.18 | DJ13: 211903.18 | DK13: 211903.18 | DL13: 211903.18 | DM13: 211903.18 | DN13: 211903.18 | DO13: 211903.18 | DP13: 211903.18 | DQ13: 211903.18 | DR13: 211903.18 | DS13: 211903.18
B14: 201803 | C14: 3027103.7 | D14: 3553883.9 | E14: 3710037.2 | F14: 3799919.6 | G14: 3799919.6 | H14: 3815193.3 | I14: 3834993.3 | J14: 3838812.3 | K14: 3841762.3 | L14: 3841762.3 | M14: 3841762.3 | N14: 3841762.3 | O14: 3841762.3 | P14: 3841762.3 | Q14: 3841762.3 | R14: 3841762.3 | S14: 3841762.3 | T14: 3841762.3 | U14: 3841762.3 | V14: 3841762.3 | W14: 3841762.3 | X14: 3841762.3 | Y14: 3841762.3 | Z14: 3841762.3 | AA14: 3841762.3 | AB14: 3841762.3 | AC14: 3841762.3 | AD14: 3841762.3 | AX14: 201803 | AY14: 3027103.7 | AZ14: 3553883.9 | BA14: 3710037.2 | BB14: 3799919.6 | BC14: 3799919.6 | BD14: 3815193.3 | BE14: 3834993.3 | BF14: 3838812.3 | BG14: 3841762.3 | BH14: 3841762.3 | BI14: 3841762.3 | BJ14: 3841762.3 | BK14: 3841762.3 | BL14: 3841762.3 | BM14: 3841762.3 | BN14: 3841762.3 | BO14: 3841762.3 | BP14: 3841762.3 | BQ14: 3841762.3 | BR14: 3841762.3 | BS14: 3841762.3 | BT14: 3841762.3 | BU14: 3841762.3 | BV14: 3841762.3 | BW14: 3841762.3 | BX14: 3841762.3 | BY14: 3841762.3 | BZ14: 3841762.3 | CP14: 201703 | CQ14: 171306 | CR14: 441166 | CS14: 450166 | CT14: 450166 | CU14: 450166 | CV14: 450166 | CW14: 450166 | CX14: 450166 | CY14: 450902.2 | CZ14: 456072.49 | DA14: 456072.49 | DB14: 456072.49 | DC14: 456072.49 | DD14: 456072.49 | DE14: 456072.49 | DF14: 456072.49 | DG14: 456072.49 | DH14: 456072.49 | DI14: 456072.49 | DJ14: 456072.49 | DK14: 456072.49 | DL14: 456072.49 | DM14: 456072.49 | DN14: 456072.49 | DO14: 456072.49 | DP14: 456072.49 | DQ14: 456072.49 | DR14: 456072.49
B15: 201806 | C15: 1919334 | D15: 3124564 | E15: 3471147.9 | F15: 3488098.9 | G15: 3488498.9 | H15: 3488498.9 | I15: 3488498.9 | J15: 3488498.9 | K15: 3488498.9 | L15: 3488498.9 | M15: 3488498.9 | N15: 3488498.9 | O15: 3488498.9 | P15: 3488498.9 | Q15: 3488498.9 | R15: 3488498.9 | S15: 3488498.9 | T15: 3488498.9 | U15: 3488498.9 | V15: 3488498.9 | W15: 3488498.9 | X15: 3488498.9 | Y15: 3488498.9 | Z15: 3488498.9 | AA15: 3488498.9 | AB15: 3488498.9 | AC15: 3488498.9 | AX15: 201806 | AY15: 1919334 | AZ15: 3124564 | BA15: 3471147.9 | BB15: 3488098.9 | BC15: 3488498.9 | BD15: 3488498.9 | BE15: 3488498.9 | BF15: 3488498.9 | BG15: 3488498.9 | BH15: 3488498.9 | BI15: 3488498.9 | BJ15: 3488498.9 | BK15: 3488498.9 | BL15: 3488498.9 | BM15: 3488498.9 | BN15: 3488498.9 | BO15: 3488498.9 | BP15: 3488498.9 | BQ15: 3488498.9 | BR15: 3488498.9 | BS15: 3488498.9 | BT15: 3488498.9 | BU15: 3488498.9 | BV15: 3488498.9 | BW15: 3488498.9 | BX15: 3488498.9 | BY15: 3488498.9 | CP15: 201706 | CQ15: 437596.4 | CR15: 1098565.3 | CS15: 1382869 | CT15: 1486179.4 | CU15: 1486179.4 | CV15: 1486179.4 | CW15: 1486179.4 | CX15: 1486179.4 | CY15: 1486179.4 | CZ15: 1486179.4 | DA15: 1486179.4 | DB15: 1486179.4 | DC15: 1486179.4 | DD15: 1486179.4 | DE15: 1486179.4 | DF15: 1486179.4 | DG15: 1486179.4 | DH15: 1486179.4 | DI15: 1486179.4 | DJ15: 1486179.4 | DK15: 1486179.4 | DL15: 1486179.4 | DM15: 1486179.4 | DN15: 1486179.4 | DO15: 1486179.4 | DP15: 1486179.4 | DQ15: 1486179.4
B16: 201809 | C16: 946217.44 | D16: 1628916.9 | E16: 1688796.1 | F16: 1693016.1 | G16: 1693016.1 | H16: 1752043 | I16: 1752043 | J16: 1755212.1 | K16: 1755212.1 | L16: 1755212.1 | M16: 1755212.1 | N16: 1755212.1 | O16: 1755212.1 | P16: 1755212.1 | Q16: 1755212.1 | R16: 1755212.1 | S16: 1755212.1 | T16: 1755212.1 | U16: 1755212.1 | V16: 1755212.1 | W16: 1755212.1 | X16: 1755212.1 | Y16: 1755212.1 | Z16: 1755212.1 | AA16: 1755212.1 | AB16: 1755212.1 | AX16: 201809 | AY16: 946217.44 | AZ16: 1628916.9 | BA16: 1688796.1 | BB16: 1693016.1 | BC16: 1693016.1 | BD16: 1752043 | BE16: 1752043 | BF16: 1755212.1 | BG16: 1755212.1 | BH16: 1755212.1 | BI16: 1755212.1 | BJ16: 1755212.1 | BK16: 1755212.1 | BL16: 1755212.1 | BM16: 1755212.1 | BN16: 1755212.1 | BO16: 1755212.1 | BP16: 1755212.1 | BQ16: 1755212.1 | BR16: 1755212.1 | BS16: 1755212.1 | BT16: 1755212.1 | BU16: 1755212.1 | BV16: 1755212.1 | BW16: 1755212.1 | BX16: 1755212.1 | CP16: 201709 | CQ16: 898347.3 | CR16: 2079772 | CS16: 2189337.1 | CT16: 2189337.1 | CU16: 2189337.1 | CV16: 2189337.1 | CW16: 2189337.1 | CX16: 2189337.1 | CY16: 2189337.1 | CZ16: 2189337.1 | DA16: 2189337.1 | DB16: 2189337.1 | DC16: 2189337.1 | DD16: 2189337.1 | DE16: 2189337.1 | DF16: 2189337.1 | DG16: 2189337.1 | DH16: 2189337.1 | DI16: 2189337.1 | DJ16: 2189337.1 | DK16: 2189337.1 | DL16: 2189337.1 | DM16: 2189337.1 | DN16: 2189337.1 | DO16: 2189337.1 | DP16: 2189337.1
B17: 201812 | C17: 529616.65 | D17: 712153.52 | E17: 844102.08 | F17: 896725.08 | G17: 909925.08 | H17: 1037929.9 | I17: 1043229.9 | J17: 1043229.9 | K17: 1046299.6 | L17: 1046299.6 | M17: 1046299.6 | N17: 1046299.6 | O17: 1046299.6 | P17: 1046299.6 | Q17: 1046299.6 | R17: 1046299.6 | S17: 1046299.6 | T17: 1046299.6 | U17: 1046299.6 | V17: 1046299.6 | W17: 1046299.6 | X17: 1046299.6 | Y17: 1046299.6 | Z17: 1046299.6 | AA17: 1046299.6 | AX17: 201812 | AY17: 529616.65 | AZ17: 712153.52 | BA17: 844102.08 | BB17: 896725.08 | BC17: 909925.08 | BD17: 1037929.9 | BE17: 1043229.9 | BF17: 1043229.9 | BG17: 1046299.6 | BH17: 1046299.6 | BI17: 1046299.6 | BJ17: 1046299.6 | BK17: 1046299.6 | BL17: 1046299.6 | BM17: 1046299.6 | BN17: 1046299.6 | BO17: 1046299.6 | BP17: 1046299.6 | BQ17: 1046299.6 | BR17: 1046299.6 | BS17: 1046299.6 | BT17: 1046299.6 | BU17: 1046299.6 | BV17: 1046299.6 | BW17: 1046299.6 | CP17: 201712 | CQ17: 608349.87 | CR17: 962919.52 | CS17: 1017800.5 | CT17: 1074284.8 | CU17: 1079397.1 | CV17: 1079397.1 | CW17: 1079397.1 | CX17: 1081997.1 | CY17: 1081997.1 | CZ17: 1081997.1 | DA17: 1087740.8 | DB17: 1087740.8 | DC17: 1087740.8 | DD17: 1087740.8 | DE17: 1087740.8 | DF17: 1087740.8 | DG17: 1087740.8 | DH17: 1087740.8 | DI17: 1087740.8 | DJ17: 1087740.8 | DK17: 1087740.8 | DL17: 1087740.8 | DM17: 1087740.8 | DN17: 1087740.8 | DO17: 1087740.8
B18: 201903 | C18: 181772.45 | D18: 1161251.3 | E18: 1542040.3 | F18: 1567720.3 | G18: 1752410.9 | H18: 1755410.9 | I18: 1755410.9 | J18: 1755410.9 | K18: 1755410.9 | L18: 1755410.9 | M18: 1755410.9 | N18: 1755410.9 | O18: 1755410.9 | P18: 1755410.9 | Q18: 1755410.9 | R18: 1825410.9 | S18: 1825410.9 | T18: 1825410.9 | U18: 1825410.9 | V18: 1825410.9 | W18: 1825410.9 | X18: 1825410.9 | Y18: 1825410.9 | Z18: 1985932.2 | AX18: 201903 | AY18: 181541.33 | AZ18: 1131975.1 | BA18: 1416931.7 | BB18: 1439406 | BC18: 1624096.6 | BD18: 1627096.6 | BE18: 1627096.6 | BF18: 1627096.6 | BG18: 1627096.6 | BH18: 1627096.6 | BI18: 1627096.6 | BJ18: 1627096.6 | BK18: 1627096.6 | BL18: 1627096.6 | BM18: 1627096.6 | BN18: 1697096.6 | BO18: 1697096.6 | BP18: 1697096.6 | BQ18: 1697096.6 | BR18: 1697096.6 | BS18: 1697096.6 | BT18: 1697096.6 | BU18: 1697096.6 | BV18: 1857617.9 | CP18: 201803 | CQ18: 3027103.7 | CR18: 3553883.9 | CS18: 3710037.2 | CT18: 3799919.6 | CU18: 3799919.6 | CV18: 3815193.3 | CW18: 3834993.3 | CX18: 3838812.3 | CY18: 3841762.3 | CZ18: 3841762.3 | DA18: 3841762.3 | DB18: 3841762.3 | DC18: 3841762.3 | DD18: 3841762.3 | DE18: 3841762.3 | DF18: 3841762.3 | DG18: 3841762.3 | DH18: 3841762.3 | DI18: 3841762.3 | DJ18: 3841762.3 | DK18: 3841762.3 | DL18: 3841762.3 | DM18: 3841762.3 | DN18: 3841762.3
B19: 201906 | C19: 380622 | D19: 955347.32 | E19: 1154492.6 | F19: 1155722.6 | G19: 1391217.4 | H19: 1410066.8 | I19: 1413035.6 | J19: 1413035.6 | K19: 1413035.6 | L19: 1413035.6 | M19: 1413035.6 | N19: 1413035.6 | O19: 1413035.6 | P19: 1413035.6 | Q19: 1413035.6 | R19: 1413035.6 | S19: 1413035.6 | T19: 1413035.6 | U19: 1413035.6 | V19: 1413035.6 | W19: 1413035.6 | X19: 1413035.6 | Y19: 1413035.6 | AX19: 201906 | AY19: 313171.21 | AZ19: 823395.75 | BA19: 988082.56 | BB19: 989312.56 | BC19: 1158382.2 | BD19: 1172926.8 | BE19: 1175004.9 | BF19: 1175004.9 | BG19: 1175004.9 | BH19: 1175004.9 | BI19: 1175004.9 | BJ19: 1175004.9 | BK19: 1175004.9 | BL19: 1175004.9 | BM19: 1175004.9 | BN19: 1175004.9 | BO19: 1175004.9 | BP19: 1175004.9 | BQ19: 1175004.9 | BR19: 1175004.9 | BS19: 1175004.9 | BT19: 1175004.9 | BU19: 1175004.9 | CP19: 201806 | CQ19: 1919334 | CR19: 3124564 | CS19: 3471147.9 | CT19: 3488098.9 | CU19: 3488498.9 | CV19: 3488498.9 | CW19: 3488498.9 | CX19: 3488498.9 | CY19: 3488498.9 | CZ19: 3488498.9 | DA19: 3488498.9 | DB19: 3488498.9 | DC19: 3488498.9 | DD19: 3488498.9 | DE19: 3488498.9 | DF19: 3488498.9 | DG19: 3488498.9 | DH19: 3488498.9 | DI19: 3488498.9 | DJ19: 3488498.9 | DK19: 3488498.9 | DL19: 3488498.9 | DM19: 3488498.9
B20: 201909 | C20: 322558.79 | D20: 1995013.9 | E20: 2052455.7 | F20: 2261343.3 | G20: 2321343.3 | H20: 2324666.8 | I20: 2324666.8 | J20: 2324666.8 | K20: 2324666.8 | L20: 2356749.7 | M20: 2356749.7 | N20: 2356749.7 | O20: 2356749.7 | P20: 2356749.7 | Q20: 2356749.7 | R20: 2356749.7 | S20: 2356749.7 | T20: 2356749.7 | U20: 2356749.7 | V20: 2356749.7 | W20: 2356749.7 | X20: 2356749.7 | AX20: 201909 | AY20: 258941.4 | AZ20: 1390893.3 | BA20: 1445192.7 | BB20: 1581781 | BC20: 1624734.2 | BD20: 1627060.6 | BE20: 1627060.6 | BF20: 1627060.6 | BG20: 1627060.6 | BH20: 1649518.6 | BI20: 1649518.6 | BJ20: 1649518.6 | BK20: 1649518.6 | BL20: 1649518.6 | BM20: 1649518.6 | BN20: 1649518.6 | BO20: 1649518.6 | BP20: 1649518.6 | BQ20: 1649518.6 | BR20: 1649518.6 | BS20: 1649518.6 | BT20: 1649518.6 | CP20: 201809 | CQ20: 946217.44 | CR20: 1628916.9 | CS20: 1688796.1 | CT20: 1693016.1 | CU20: 1693016.1 | CV20: 1752043 | CW20: 1752043 | CX20: 1755212.1 | CY20: 1755212.1 | CZ20: 1755212.1 | DA20: 1755212.1 | DB20: 1755212.1 | DC20: 1755212.1 | DD20: 1755212.1 | DE20: 1755212.1 | DF20: 1755212.1 | DG20: 1755212.1 | DH20: 1755212.1 | DI20: 1755212.1 | DJ20: 1755212.1 | DK20: 1755212.1 | DL20: 1755212.1
B21: 201912 | C21: 465392.41 | D21: 3063217.1 | E21: 3457316.2 | F21: 3492814.7 | G21: 3501187.6 | H21: 3503551.4 | I21: 3753551.4 | J21: 3755640.6 | K21: 3755640.6 | L21: 3755640.6 | M21: 3755640.6 | N21: 3755640.6 | O21: 3755640.6 | P21: 3755640.6 | Q21: 3755640.6 | R21: 3755640.6 | S21: 3755640.6 | T21: 3755640.6 | U21: 3755640.6 | V21: 3755640.6 | W21: 3755640.6 | AX21: 201912 | AY21: 341307.1 | AZ21: 2162107.7 | BA21: 2438052.1 | BB21: 2464398 | BC21: 2470259 | BD21: 2471913.7 | BE21: 2646913.7 | BF21: 2648376.2 | BG21: 2648376.2 | BH21: 2648376.2 | BI21: 2648376.2 | BJ21: 2648376.2 | BK21: 2648376.2 | BL21: 2648376.2 | BM21: 2648376.2 | BN21: 2648376.2 | BO21: 2648376.2 | BP21: 2648376.2 | BQ21: 2648376.2 | BR21: 2648376.2 | BS21: 2648376.2 | CP21: 201812 | CQ21: 529616.65 | CR21: 712153.52 | CS21: 844102.08 | CT21: 896725.08 | CU21: 909925.08 | CV21: 1037929.9 | CW21: 1043229.9 | CX21: 1043229.9 | CY21: 1046299.6 | CZ21: 1046299.6 | DA21: 1046299.6 | DB21: 1046299.6 | DC21: 1046299.6 | DD21: 1046299.6 | DE21: 1046299.6 | DF21: 1046299.6 | DG21: 1046299.6 | DH21: 1046299.6 | DI21: 1046299.6 | DJ21: 1046299.6 | DK21: 1046299.6
